Workbook

Sheet Propia
B1: JIC | G1: Propias | O1: Propias
E2: IPT JIC | H2: ARG | L2: USA | M2: USA | O2: IPC + IPI Indutrial | Q2: IPC + ENGE ind | S2: IPC + ENGE ind | U2: IPC
B3: TCC | C3: Paridad por ipi + ipc | D3: Paridad por IPC | G3: TCC | H3: IPC | I3: IPT Industria | J3: IPT ENGE | K3: IPT ENGE | L3: IPC | M3: IPT Industrai | O3: Paridad | P3: Sobrevaluación | Q3: Paridad | R3: Sobrevaluación | S3: Paridad | T3: Sobrevaluación | U3: Paridad | V3: Sobrevaluación
H4: 2004=1 | I4: 1997=100 | J4: sin imp | K4: con imp | Q4: Sin imp | S4: Con imp
A5: 1990 | H5: 0.16858592 | L5: 0.9045 | M5: 73.92291
A6: 1991 | B6: 0.95 | C6: 1.69 | D6: 1.59 | E6: 0.647 | G6: 0.95 | H6: 0.45800023 | I6: =I7*E6/E7 -> 59.329216 | J6: =J7*I6/I7 -> 69.660713 | K6: =K7*I6/I7 -> 65.842412 | L6: 0.9426 | M6: 75.612484 | O6: =C6 -> 1.69 | P6: =O6/G6 -> 1.7789474 | Q6: =C6 -> 1.69 | R6: =Q6/G6 -> 1.7789474 | S6: =C6 -> 1.69 | T6: =S6/G6 -> 1.7789474 | U6: =D6 -> 1.59 | V6: =U6/G6 -> 1.6736842
A7: 1992 | B7: 0.99 | C7: 1.9 | D7: 1.93 | E7: 0.737 | G7: 0.99 | H7: 0.57204205 | I7: =I8*E7/E8 -> 67.582121 | J7: =J8*I7/I8 -> 79.350766 | K7: =K8*I7/I8 -> 75.001325 | L7: 0.9709 | M7: 79.605043 | O7: =O6*((H7/H6)/(L7/L6))*((M7/M6)/(I7/I6)) -> 1.8940253 | P7: =O7/G7 -> 1.9131568 | Q7: =Q6*((H7/H6)/(L7/L6))*((M7/M6)/(J7/J6)) -> 1.8940253 | R7: =Q7/G7 -> 1.9131568 | S7: =S6*((H7/H6)/(L7/L6))*((M7/M6)/(K7/K6)) -> 1.8940253 | T7: =S7/G7 -> 1.9131568 | U7: =U6*(H7/H6)/(L7/L6) -> 1.9280235 | V7: =U7/G7 -> 1.9474985
A8: 1993 | B8: 0.99 | C8: 1.97 | D8: 2.07 | E8: 0.785 | G8: 0.99 | H8: 0.63274437 | I8: 71.98367 | J8: 84.518794 | K8: 79.886079 | L8: 1 | M8: 82.204164 | O8: =O7*((H8/H7)/(L8/L7))*((M8/M7)/(I8/I7)) -> 1.9720216 | P8: =O8/G8 -> 1.991941 | Q8: =Q7*((H8/H7)/(L8/L7))*((M8/M7)/(J8/J7)) -> 1.9720216 | R8: =Q8/G8 -> 1.991941 | S8: =S7*((H8/H7)/(L8/L7))*((M8/M7)/(K8/K7)) -> 1.9720216 | T8: =S8/G8 -> 1.991941 | U8: =U7*(H8/H7)/(L8/L7) -> 2.0705568 | V8: =U8/G8 -> 2.0914716
A9: 1994 | B9: 1 | C9: 1.98 | D9: 2.1 | G9: 1 | H9: 0.65917624 | I9: 82.547503 | J9: 99.06571 | K9: 91.674682 | L9: 1.026 | M9: 85.320435 | O9: =O8*((H9/H8)/(L9/L8))*((M9/M8)/(I9/I8)) -> 1.8122865 | P9: =O9/G9 -> 1.8122865 | Q9: =Q8*((H9/H8)/(L9/L8))*((M9/M8)/(J9/J8)) -> 1.7730735 | R9: =Q9/G9 -> 1.7730735 | S9: =S8*((H9/H8)/(L9/L8))*((M9/M8)/(K9/K8)) -> 1.8110002 | T9: =S9/G9 -> 1.8110002 | U9: =U8*(H9/H8)/(L9/L8) -> 2.1023889 | V9: =U9/G9 -> 2.1023889
A10: 1995 | B10: 0.99 | C10: 2.07 | D10: 2.11 | G10: 0.99 | H10: 0.68143068 | I10: 84.240539 | J10: 94.003401 | K10: 86.088607 | L10: 1.055 | M10: 88.411072 | O10: =O9*((H10/H9)/(L10/L9))*((M10/M9)/(I10/I9)) -> 1.850028 | P10: =O10/G10 -> 1.8687151 | Q10: =Q9*((H10/H9)/(L10/L9))*((M10/M9)/(J10/J9)) -> 1.9465931 | R10: =Q10/G10 -> 1.9662556 | S10: =S9*((H10/H9)/(L10/L9))*((M10/M9)/(K10/K9)) -> 2.0090506 | T10: =S10/G10 -> 2.029344 | U10: =U9*(H10/H9)/(L10/L9) -> 2.1136257 | V10: =U10/G10 -> 2.1349755
A11: 1996 | B11: 1 | C11: 1.89 | D11: 2.06 | G11: 1 | H11: 0.68249151 | I11: 94.110664 | J11: 98.592739 | K11: 93.064174 | L11: 1.086 | M11: 93.284375 | O11: =O10*((H11/H10)/(L11/L10))*((M11/M10)/(I11/I10)) -> 1.7000475 | P11: =O11/G11 -> 1.7000475 | Q11: =Q10*((H11/H10)/(L11/L10))*((M11/M10)/(J11/J10)) -> 1.9053478 | R11: =Q11/G11 -> 1.9053478 | S11: =S10*((H11/H10)/(L11/L10))*((M11/M10)/(K11/K10)) -> 1.9078951 | T11: =S11/G11 -> 1.9078951 | U11: =U10*(H11/H10)/(L11/L10) -> 2.0564886 | V11: =U11/G11 -> 2.0564886
A12: 1997 | B12: 1 | C12: 1.79 | D12: 2.02 | G12: 1 | H12: 0.68609908 | I12: 100 | J12: 100 | K12: 100 | L12: 1.111 | M12: 100 | O12: =O11*((H12/H11)/(L12/L11))*((M12/M11)/(I12/I11)) -> 1.6853742 | P12: =O12/G12 -> 1.6853742 | Q12: =Q11*((H12/H11)/(L12/L11))*((M12/M11)/(J12/J11)) -> 1.9788626 | R12: =Q12/G12 -> 1.9788626 | S12: =S11*((H12/H11)/(L12/L11))*((M12/M11)/(K12/K11)) -> 1.8703955 | T12: =S12/G12 -> 1.8703955 | U12: =U11*(H12/H11)/(L12/L11) -> 2.0208387 | V12: =U12/G12 -> 2.0208387
A13: 1998 | B13: 1 | C13: 1.8 | D13: 2.01 | G13: 1 | H13: 0.6924432 | I13: 97.080398 | J13: 105.40486 | K13: 104.37148 | L13: 1.128 | M13: 106.27677 | O13: =O12*((H13/H12)/(L13/L12))*((M13/M12)/(I13/I12)) -> 1.8340257 | P13: =O13/G13 -> 1.8340257 | Q13: =Q12*((H13/H12)/(L13/L12))*((M13/M12)/(J13/J12)) -> 1.9833329 | R13: =Q13/G13 -> 1.9833329 | S13: =S12*((H13/H12)/(L13/L12))*((M13/M12)/(K13/K12)) -> 1.8931814 | T13: =S13/G13 -> 1.8931814 | U13: =U12*(H13/H12)/(L13/L12) -> 2.0087872 | V13: =U13/G13 -> 2.0087872
A14: 1999 | B14: 1 | C14: 1.85 | D14: 1.94 | G14: 1 | H14: 0.68436463 | I14: 94.596914 | J14: 96.727279 | K14: 100.86458 | L14: 1.153 | M14: 113.60723 | O14: =O13*((H14/H13)/(L14/L13))*((M14/M13)/(I14/I13)) -> 1.9454084 | P14: =O14/G14 -> 1.9454084 | Q14: =Q13*((H14/H13)/(L14/L13))*((M14/M13)/(J14/J13)) -> 2.233871 | R14: =Q14/G14 -> 2.233871 | S14: =S13*((H14/H13)/(L14/L13))*((M14/M13)/(K14/K13)) -> 2.0248189 | T14: =S14/G14 -> 2.0248189 | U14: =U13*(H14/H13)/(L14/L13) -> 1.9423036 | V14: =U14/G14 -> 1.9423036
A15: 2000 | B15: 1 | C15: 1.74 | D15: 1.86 | G15: 1 | H15: 0.67793771 | I15: 94.14454 | J15: 105.26128 | K15: 109.76361 | L15: 1.192 | M15: 119.46064 | O15: =O14*((H15/H14)/(L15/L14))*((M15/M14)/(I15/I14)) -> 1.969549 | P15: =O15/G15 -> 1.969549 | Q15: =Q14*((H15/H14)/(L15/L14))*((M15/M14)/(J15/J14)) -> 2.0682954 | R15: =Q15/G15 -> 2.0682954 | S15: =S14*((H15/H14)/(L15/L14))*((M15/M14)/(K15/K14)) -> 1.8747384 | T15: =S15/G15 -> 1.8747384 | U15: =U14*(H15/H14)/(L15/L14) -> 1.8611115 | V15: =U15/G15 -> 1.8611115
A16: 2001 | B16: 1 | C16: 1.79 | D16: 1.79 | G16: 1 | H16: 0.67071426 | I16: 88.349002 | J16: 105.24287 | K16: 108.941 | L16: 1.226 | M16: 122.78976 | O16: =O15*((H16/H15)/(L16/L15))*((M16/M15)/(I16/I15)) -> 2.0750622 | P16: =O16/G16 -> 2.0750622 | Q16: =Q15*((H16/H15)/(L16/L15))*((M16/M15)/(J16/J15)) -> 2.0453112 | R16: =Q16/G16 -> 2.0453112 | S16: =S15*((H16/H15)/(L16/L15))*((M16/M15)/(K16/K15)) -> 1.867577 | T16: =S16/G16 -> 1.867577 | U16: =U15*(H16/H15)/(L16/L15) -> 1.7902181 | V16: =U16/G16 -> 1.7902181
A17: 2002 | B17: 3.14 | C17: 2.4 | D17: 2.22 | G17: 3.14 | H17: 0.84421828 | I17: 79.988317 | J17: 131.5327 | K17: 133.80529 | L17: 1.245 | M17: 134.07299 | O17: =O16*((H17/H16)/(L17/L16))*((M17/M16)/(I17/I16)) -> 3.1018707 | P17: =O17/G17 -> 0.98785691 | Q17: =Q16*((H17/H16)/(L17/L16))*((M17/M16)/(J17/J16)) -> 2.2148066 | R17: =Q17/G17 -> 0.70535241 | S17: =S16*((H17/H16)/(L17/L16))*((M17/M16)/(K17/K16)) -> 2.0578518 | T17: =S17/G17 -> 0.65536681 | U17: =U16*(H17/H16)/(L17/L16) -> 2.2189334 | V17: =U17/G17 -> 0.70666669
A18: 2003 | B18: 2.93 | C18: 2.53 | D18: 2.46 | G18: 2.93 | H18: 0.95770776 | I18: 82.662494 | J18: 128.7609 | K18: 140.48616 | L18: 1.273 | M18: 143.95953 | O18: =O17*((H18/H17)/(L18/L17))*((M18/M17)/(I18/I17)) -> 3.5756917 | P18: =O18/G18 -> 1.2203726 | Q18: =Q17*((H18/H17)/(L18/L17))*((M18/M17)/(J18/J17)) -> 2.6952798 | R18: =Q18/G18 -> 0.91989073 | S18: =S17*((H18/H17)/(L18/L17))*((M18/M17)/(K18/K17)) -> 2.3349208 | T18: =S18/G18 -> 0.79690129 | U18: =U17*(H18/H17)/(L18/L17) -> 2.4618607 | V18: =U18/G18 -> 0.84022549
A19: 2004 | B19: 2.93 | C19: 2.64 | D19: 2.5 | G19: 2.93 | H19: 1 | I19: 90.338934 | J19: 146.52488 | K19: 153.99498 | L19: 1.307 | M19: 150.40394 | O19: =O18*((H19/H18)/(L19/L18))*((M19/M18)/(I19/I18)) -> 3.4764197 | P19: =O19/G19 -> 1.1864914 | Q19: =Q18*((H19/H18)/(L19/L18))*((M19/M18)/(J19/J18)) -> 2.5166052 | R19: =Q19/G19 -> 0.85890961 | S19: =S18*((H19/H18)/(L19/L18))*((M19/M18)/(K19/K18)) -> 2.263277 | T19: =S19/G19 -> 0.77244949 | U19: =U18*(H19/H18)/(L19/L18) -> 2.5037057 | V19: =U19/G19 -> 0.85450707
A20: =A19+1 -> 2005 | G20: 2.9284167 | H20: 1.096424 | I20: 88.878478 | J20: 142.18761 | K20: 154.65523 | L20: 1.3518099 | M20: 157.15477 | O20: =O19*((H20/H19)/(L20/L19))*((M20/M19)/(I20/I19)) -> 3.9139695 | P20: =O20/G20 -> 1.336548 | Q20: =Q19*((H20/H19)/(L20/L19))*((M20/M19)/(J20/J19)) -> 2.8725764 | R20: =Q20/G20 -> 0.98093158 | S20: =S19*((H20/H19)/(L20/L19))*((M20/M19)/(K20/K19)) -> 2.4962412 | T20: =S20/G20 -> 0.85242008 | U20: =U19*(H20/H19)/(L20/L19) -> 2.6541275 | V20: =U20/G20 -> 0.90633534
A21: =A20+1 -> 2006 | G21: 3.07775 | H21: 1.2089396 | I21: 91.964433 | J21: 144.27253 | K21: 156.92362 | L21: 1.3954826 | M21: 160.29438 | O21: =O20*((H21/H20)/(L21/L20))*((M21/M20)/(I21/I20)) -> 4.1209954 | P21: =O21/G21 -> 1.3389636 | Q21: =Q20*((H21/H20)/(L21/L20))*((M21/M20)/(J21/J20)) -> 3.0843076 | R21: =Q21/G21 -> 1.0021307 | S21: =S20*((H21/H20)/(L21/L20))*((M21/M20)/(K21/K20)) -> 2.6802224 | T21: =S21/G21 -> 0.87083823 | U21: =U20*(H21/H20)/(L21/L20) -> 2.8349086 | V21: =U21/G21 -> 0.92109774
A22: =A21+1 -> 2007 | G22: 3.1191667 | H22: 1.4301886 | I22: 100.03275 | J22: 154.87346 | K22: 168.45438 | L22: 1.4352526 | M22: 168.20073 | O22: =O21*((H22/H21)/(L22/L21))*((M22/M21)/(I22/I21)) -> 4.5727158 | P22: =O22/G22 -> 1.4660056 | Q22: =Q21*((H22/H21)/(L22/L21))*((M22/M21)/(J22/J21)) -> 3.4678372 | R22: =Q22/G22 -> 1.1117832 | S22: =S21*((H22/H21)/(L22/L21))*((M22/M21)/(K22/K21)) -> 3.0135001 | T22: =S22/G22 -> 0.96612347 | U22: =U21*(H22/H21)/(L22/L21) -> 3.2607976 | V22: =U22/G22 -> 1.0454066
A23: =A22+1 -> 2008 | G23: 3.1831667 | H23: 1.8171998 | I23: 98.958019 | J23: 155.51686 | K23: 169.15405 | L23: 1.490271 | M23: 166.28774 | O23: =O22*((H23/H22)/(L23/L22))*((M23/M22)/(I23/I22)) -> 5.5920397 | P23: =O23/G23 -> 1.7567537 | Q23: =Q22*((H23/H22)/(L23/L22))*((M23/M22)/(J23/J22)) -> 4.1779484 | R23: =Q23/G23 -> 1.3125132 | S23: =S22*((H23/H22)/(L23/L22))*((M23/M22)/(K23/K22)) -> 3.6305796 | T23: =S23/G23 -> 1.1405559 | U23: =U22*(H23/H22)/(L23/L22) -> 3.9902152 | V23: =U23/G23 -> 1.2535364
A24: =A23+1 -> 2009 | G24: 3.75 | H24: 2.0822574 | I24: 91.364301 | J24: 136.68539 | K24: 154.23329 | L24: 1.4851002 | M24: 166.18724 | O24: =O23*((H24/H23)/(L24/L23))*((M24/M23)/(I24/I23)) -> 6.9602259 | P24: =O24/G24 -> 1.8560602 | Q24: =Q23*((H24/H23)/(L24/L23))*((M24/M23)/(J24/J23)) -> 5.4625709 | R24: =Q24/G24 -> 1.4566856 | S24: =S23*((H24/H23)/(L24/L23))*((M24/M23)/(K24/K23)) -> 4.5757139 | T24: =S24/G24 -> 1.2201904 | U24: =U23*(H24/H23)/(L24/L23) -> 4.5881491 | V24: =U24/G24 -> 1.2235064
A25: =A24+1 -> 2010 | G25: 3.89 | H25: 2.5630419 | I25: 110.38261 | J25: 145.83817 | K25: 161.59825 | L25: 1.5094977 | M25: 182.56289 | O25: =O24*((H25/H24)/(L25/L24))*((M25/M24)/(I25/I24)) -> 7.6640558 | P25: =O25/G25 -> 1.9701943 | Q25: =Q24*((H25/H24)/(L25/L24))*((M25/M24)/(J25/J24)) -> 6.8109457 | R25: =Q25/G25 -> 1.7508858 | S25: =S24*((H25/H24)/(L25/L24))*((M25/M24)/(K25/K24)) -> 5.8097812 | T25: =S25/G25 -> 1.493517 | U25: =U24*(H25/H24)/(L25/L24) -> 5.5562544 | V25: =U25/G25 -> 1.428343
A26: =A25+1 -> 2011 | G26: 4.11 | H26: 3.1636717 | I26: 111.80629 | J26: 150.39454 | K26: 164.73475 | L26: 1.5570928 | M26: 185.0506 | O26: =O25*((H26/H25)/(L26/L25))*((M26/M25)/(I26/I25)) -> 9.1775073 | P26: =O26/G26 -> 2.2329701 | Q26: =Q25*((H26/H25)/(L26/L25))*((M26/M25)/(J26/J25)) -> 8.0108423 | R26: =Q26/G26 -> 1.94911 | S26: =S25*((H26/H25)/(L26/L25))*((M26/M25)/(K26/K25)) -> 6.912623 | T26: =S26/G26 -> 1.6819034 | U26: =U25*(H26/H25)/(L26/L25) -> 6.6486852 | V26: =U26/G26 -> 1.617685
A27: =A26+1 -> 2012 | G27: 4.5525185 | H27: 3.9120057 | I27: 103.2364 | J27: 138.07466 | K27: 162.69797 | L27: 1.5893562 | M27: 186.48146 | O27: =O26*((H27/H26)/(L27/L26))*((M27/M26)/(I27/I26)) -> 12.134017 | P27: =O27/G27 -> 2.6653417 | Q27: =Q26*((H27/H26)/(L27/L26))*((M27/M26)/(J27/J26)) -> 10.652285 | R27: =Q27/G27 -> 2.3398664 | S27: =S26*((H27/H26)/(L27/L26))*((M27/M26)/(K27/K26)) -> 8.5446136 | T27: =S27/G27 -> 1.8768982 | U27: =U26*(H27/H26)/(L27/L26) -> 8.0544725 | V27: =U27/G27 -> 1.7692344
A28: =A27+1 -> 2013 | G28: 5.49 | H28: 4.9091424 | I28: 105.30892 | J28: 138.02823 | K28: 160.76765 | L28: 1.6126493 | M28: 188.12902 | O28: =O27*((H28/H27)/(L28/L27))*((M28/M27)/(I28/I27)) -> 14.841572 | P28: =O28/G28 -> 2.7033829 | Q28: =Q27*((H28/H27)/(L28/L27))*((M28/M27)/(J28/J27)) -> 13.295247 | R28: =Q28/G28 -> 2.4217208 | S28: =S27*((H28/H27)/(L28/L27))*((M28/M27)/(K28/K27)) -> 10.789058 | T28: =S28/G28 -> 1.96522 | U28: =U27*(H28/H27)/(L28/L27) -> 9.9614962 | V28: =U28/G28 -> 1.8144802
A29: =A28+1 -> 2014 | G29: 8.1236 | H29: 6.8027962 | I29: 99.408903 | J29: 135.04194 | K29: 158.33275 | L29: 1.6387851 | M29: 187.27417 | O29: =O28*((H29/H28)/(L29/L28))*((M29/M28)/(I29/I28)) -> 21.342318 | P29: =O29/G29 -> 2.6271996 | Q29: =Q28*((H29/H28)/(L29/L28))*((M29/M28)/(J29/J28)) -> 18.446651 | R29: =Q29/G29 -> 2.2707483 | S29: =S28*((H29/H28)/(L29/L28))*((M29/M28)/(K29/K28)) -> 14.870763 | T29: =S29/G29 -> 1.8305631 | U29: =U28*(H29/H28)/(L29/L28) -> 13.583895 | V29: =U29/G29 -> 1.6721521
A30: =A29+1 -> 2015 | G30: 9.43 | H30: 8.5686951 | I30: 102.5195 | J30: 145.11022 | K30: 160.5523 | L30: 1.647 | M30: 183.98915 | O30: =O29*((H30/H29)/(L30/L29))*((M30/M29)/(I30/I29)) -> 25.481816 | P30: =O30/G30 -> 2.7022074 | Q30: =Q29*((H30/H29)/(L30/L29))*((M30/M29)/(J30/J29)) -> 21.137722 | R30: =Q30/G30 -> 2.2415399 | S30: =S29*((H30/H29)/(L30/L29))*((M30/M29)/(K30/K29)) -> 18.057492 | T30: =S30/G30 -> 1.9148984 | U30: =U29*(H30/H29)/(L30/L29) -> 17.024719 | V30: =U30/G30 -> 1.8053785
A31: =A30+1 -> 2016 | G31: 14.777446 | H31: 12.115232 | I31: 99.170058 | J31: 137.28909 | K31: 151.66151 | L31: 1.6677771 | M31: 182.99238 | O31: =O30*((H31/H30)/(L31/L30))*((M31/M30)/(I31/I30)) -> 36.582193 | P31: =O31/G31 -> 2.4755423 | Q31: =Q30*((H31/H30)/(L31/L30))*((M31/M30)/(J31/J30)) -> 31.026557 | R31: =Q31/G31 -> 2.0995885 | S31: =S30*((H31/H30)/(L31/L30))*((M31/M30)/(K31/K30)) -> 26.546792 | T31: =S31/G31 -> 1.7964397 | U31: =U30*(H31/H30)/(L31/L30) -> 23.771282 | V31: =U31/G31 -> 1.6086191
... A38: =A37+1 -> 2023 | G38: 295.2949 | H38: 267.69791 | I38: 88.487678 | J38: 115.23585 | K38: 114.61515 | L38: 2.0945627 | M38: 176.24785 | O38: =O37*((H38/H37)/(L38/L37))*((M38/M37)/(I38/I37)) -> 694.73024 | P38: =O38/G38 -> 2.3526659 | Q38: =Q37*((H38/H37)/(L38/L37))*((M38/M37)/(J38/J37)) -> 626.36964 | R38: =Q38/G38 -> 2.1211665 | S38: =S37*((H38/H37)/(L38/L37))*((M38/M37)/(K38/K37)) -> 595.24273 | T38: =S38/G38 -> 2.0157569 | U38: =U37*(H38/H37)/(L38/L37) -> 418.22548 | V38: =U38/G38 -> 1.4162977
A39: =A38+1 -> 2024 | G39: 959.27235 | H39: 855.79575 | I39: 82.088881 | J39: =J38 -> 115.23585 | K39: =K38 -> 114.61515 | L39: 2.1081294 | M39: 177.31754 | O39: =O38*((H39/H38)/(L39/L38))*((M39/M38)/(I39/I38)) -> 2393.1162 | P39: =O39/G39 -> 2.4947202 | Q39: =Q38*((H39/H38)/(L39/L38))*((M39/M38)/(J39/J38)) -> 2001.6116 | R39: =Q39/G39 -> 2.0865936 | S39: =S38*((H39/H38)/(L39/L38))*((M39/M38)/(K39/K38)) -> 1902.1432 | T39: =S39/G39 -> 1.9829021 | U39: =U38*(H39/H38)/(L39/L38) -> 1328.4087 | V39: =U39/G39 -> 1.3848087
A40: 45658 | G40: 1069.147 | H40: 874.62326 | I40: =I39 -> 82.088881 | J40: =J39 -> 115.23585 | K40: =K39 -> 114.61515 | L40: =L39 -> 2.1081294 | M40: =M39 -> 177.31754 | O40: =O39*((H40/H39)/(L40/L39))*((M40/M39)/(I40/I39)) -> 2445.7647 | P40: =O40/G40 -> 2.2875851 | Q40: =Q39*((H40/H39)/(L40/L39))*((M40/M39)/(J40/J39)) -> 2045.6471 | R40: =Q40/G40 -> 1.913345 | S40: =S39*((H40/H39)/(L40/L39))*((M40/M39)/(K40/K39)) -> 1943.9904 | T40: =S40/G40 -> 1.8182629 | U40: =U39*(H40/H39)/(L40/L39) -> 1357.6337 | V40: =U40/G40 -> 1.2698289
A41: 45689 | G41: 1085.11 | H41: 895.61422 | I41: =I40 -> 82.088881 | J41: =J40 -> 115.23585 | K41: =K40 -> 114.61515 | L41: =L40 -> 2.1081294 | M41: =M40 -> 177.31754 | O41: =O40*((H41/H40)/(L41/L40))*((M41/M40)/(I41/I40)) -> 2504.4631 | P41: =O41/G41 -> 2.3080269 | Q41: =Q40*((H41/H40)/(L41/L40))*((M41/M40)/(J41/J40)) -> 2094.7426 | R41: =Q41/G41 -> 1.9304426 | S41: =S40*((H41/H40)/(L41/L40))*((M41/M40)/(K41/K40)) -> 1990.6461 | T41: =S41/G41 -> 1.8345109 | U41: =U40*(H41/H40)/(L41/L40) -> 1390.2169 | V41: =U41/G41 -> 1.281176
A42: 45717 | G42: 1105.7756 | H42: 928.75194 | I42: =I41 -> 82.088881 | J42: =J41 -> 115.23585 | K42: =K41 -> 114.61515 | L42: =L41 -> 2.1081294 | M42: =M41 -> 177.31754 | O42: =O41*((H42/H41)/(L42/L41))*((M42/M41)/(I42/I41)) -> 2597.1282 | P42: =O42/G42 -> 2.3486938 | Q42: =Q41*((H42/H41)/(L42/L41))*((M42/M41)/(J42/J41)) -> 2172.2481 | R42: =Q42/G42 -> 1.9644566 | S42: =S41*((H42/H41)/(L42/L41))*((M42/M41)/(K42/K41)) -> 2064.3 | T42: =S42/G42 -> 1.8668346 | U42: =U41*(H42/H41)/(L42/L41) -> 1441.655 | V42: =U42/G42 -> 1.3037501
A43: 45748 | G43: 1145.6658 | H43: 954.757 | I43: =I42 -> 82.088881 | J43: =J42 -> 115.23585 | K43: =K42 -> 114.61515 | L43: =L42 -> 2.1081294 | M43: =M42 -> 177.31754 | O43: =O42*((H43/H42)/(L43/L42))*((M43/M42)/(I43/I42)) -> 2669.8478 | P43: =O43/G43 -> 2.3303897 | Q43: =Q42*((H43/H42)/(L43/L42))*((M43/M42)/(J43/J42)) -> 2233.071 | R43: =Q43/G43 -> 1.949147 | S43: =S42*((H43/H42)/(L43/L42))*((M43/M42)/(K43/K42)) -> 2122.1004 | T43: =S43/G43 -> 1.8522858 | U43: =U42*(H43/H42)/(L43/L42) -> 1482.0213 | V43: =U43/G43 -> 1.2935896
A44: 45778 | G44: 1146.2105 | H44: 969.07835 | I44: =I43 -> 82.088881 | J44: =J43 -> 115.23585 | K44: =K43 -> 114.61515 | L44: =L43 -> 2.1081294 | M44: =M43 -> 177.31754 | O44: =O43*((H44/H43)/(L44/L43))*((M44/M43)/(I44/I43)) -> 2709.8955 | P44: =O44/G44 -> 2.3642214 | Q44: =Q43*((H44/H43)/(L44/L43))*((M44/M43)/(J44/J43)) -> 2266.5671 | R44: =Q44/G44 -> 1.9774439 | S44: =S43*((H44/H43)/(L44/L43))*((M44/M43)/(K44/K43)) -> 2153.9319 | T44: =S44/G44 -> 1.8791765 | U44: =U43*(H44/H43)/(L44/L43) -> 1504.2516 | V44: =U44/G44 -> 1.3123694
A45: 45809 | G45: 1181.1 | H45: 984.58361 | I45: =I44 -> 82.088881 | J45: =J44 -> 115.23585 | K45: =K44 -> 114.61515 | L45: =L44 -> 2.1081294 | M45: =M44 -> 177.31754 | O45: =O44*((H45/H44)/(L45/L44))*((M45/M44)/(I45/I44)) -> 2753.2538 | P45: =O45/G45 -> 2.3310929 | Q45: =Q44*((H45/H44)/(L45/L44))*((M45/M44)/(J45/J44)) -> 2302.8321 | R45: =Q45/G45 -> 1.9497351 | S45: =S44*((H45/H44)/(L45/L44))*((M45/M44)/(K45/K44)) -> 2188.3948 | T45: =S45/G45 -> 1.8528447 | U45: =U44*(H45/H44)/(L45/L44) -> 1528.3196 | V45: =U45/G45 -> 1.2939799

Sheet Largo Plazo
B1: JIC | I1: Propias | Q1: Propias
E2: IPT Arg JIC | F2: IPT USA | J2: ARG | N2: USA | O2: USA | Q2: IPC + IPI Indutrial | U2: IPC + ENGE ind sin imp | Y2: IPC + ENGE ind con imp | AC2: IPC
B3: TCC | C3: Paridad por ipi + ipc | D3: Paridad por IPC | I3: TCC | J3: IPC | K3: IPT Industria | L3: IPT ENGE | M3: IPT ENGE | N3: IPC | O3: IPT Industrai | Q3: TCP arb | R3: TCP arb/TCC | S3: Sobrevaluación | T3: TCP | U3: TCP arb | V3: TCP arb/TCC | W3: Sobrevaluación | X3: TCP | Y3: TCP arb | Z3: TCP arb/TCC | AA3: Sobrevaluación | AB3: TCP | AC3: TCP arb | AD3: TCP arb/TCC | AE3: Sobrevaluación | AF3: TCP
J4: 2004=1 | K4: 1997=100 | L4: sin imp | M4: con imp
A5: Promedio 1959-1972 | I5: =AVERAGE(I30:I43) -> 2.6316429e-11 | J5: =AVERAGE(J30:J43) -> 2.080443e-12 | K5: =AVERAGE(K30:K43) -> 30.463699 | L5: =AVERAGE(L30:L43) -> 35.7686 | M5: =AVERAGE(M30:M43) -> 33.808021 | N5: =AVERAGE(N30:N43) -> 0.23247143 | O5: =AVERAGE(O30:O43) -> 36.246788 | R5: =AVERAGE(R30:R43) -> 0.91451806 | V5: =AVERAGE(V30:V43) -> 0.91451806 | Z5: =AVERAGE(Z30:Z43) -> 0.91451806 | AD5: =AVERAGE(AD30:AD43) -> 0.91249691
A7: =A8-1 -> 1936 | C7: 2.94e-13 | E7: 0.223 | F7: 0.186 | I7: 3.01e-13 | J7: 1.1740506e-14 | K7: =K8*E7/E8 -> 20.448864 | L7: =L8*K7/K8 -> 24.009798 | M7: =M8*K7/K8 -> 22.693752 | N7: 0.09619 | O7: =O8*F7/F8 -> 18.067886 | Q7: =I$5*((J7/J$5)/(N7/N$5))*((O7/O$5)/(K7/K$5)) -> 2.6653169e-13 | R7: =Q7/I7 -> 0.88548736 | S7: =R7/R$5 -> 0.96825573 | T7: =S7*I7 -> 2.9144498e-13 | U7: =I$5*((J7/J$5)/(N7/N$5))*((O7/O$5)/(L7/L$5)) -> 2.6653169e-13 | V7: =U7/I7 -> 0.88548736 | W7: =V7/V$5 -> 0.96825573 | X7: =W7*I7 -> 2.9144498e-13 | Y7: =I$5*((J7/J$5)/(N7/N$5))*((O7/O$5)/(M7/M$5)) -> 2.6653169e-13 | Z7: =Y7/I7 -> 0.88548736 | AA7: =Z7/Z$5 -> 0.96825573 | AB7: =AA7*I7 -> 2.9144498e-13 | AC7: =I$5*((J7/J$5)/(N7/N$5)) -> 3.5891996e-13 | AD7: =AC7/I7 -> 1.1924251 | AE7: =AD7/AD$5 -> 1.3067717 | AF7: =AE7*I7 -> 3.9333827e-13
A8: =A9-1 -> 1937 | C8: 2.87e-13 | E8: 0.225 | F8: 0.185 | I8: 3.03e-13 | J8: 1.2050633e-14 | K8: =K9*E8/E9 -> 20.632262 | L8: =L9*K8/K9 -> 24.225132 | M8: =M9*K8/K9 -> 22.897284 | N8: 0.09965 | O8: =O9*F8/F9 -> 17.970747 | Q8: =I$5*((J8/J$5)/(N8/N$5))*((O8/O$5)/(K8/K$5)) -> 2.6031886e-13 | R8: =Q8/I8 -> 0.85913817 | S8: =R8/R$5 -> 0.93944363 | T8: =S8*I8 -> 2.8465142e-13 | U8: =I$5*((J8/J$5)/(N8/N$5))*((O8/O$5)/(L8/L$5)) -> 2.6031886e-13 | V8: =U8/I8 -> 0.85913817 | W8: =V8/V$5 -> 0.93944363 | X8: =W8*I8 -> 2.8465142e-13 | Y8: =I$5*((J8/J$5)/(N8/N$5))*((O8/O$5)/(M8/M$5)) -> 2.6031886e-13 | Z8: =Y8/I8 -> 0.85913817 | AA8: =Z8/Z$5 -> 0.93944363 | AB8: =AA8*I8 -> 2.8465142e-13 | AC8: =I$5*((J8/J$5)/(N8/N$5)) -> 3.5560942e-13 | AD8: =AC8/I8 -> 1.1736285 | AE8: =AD8/AD$5 -> 1.2861725 | AF8: =AE8*I8 -> 3.8971027e-13
A9: =A10-1 -> 1938 | C9: 2.64e-13 | E9: 0.224 | F9: 0.167 | I9: 3.07e-13 | J9: 1.1968354e-14 | K9: =K10*E9/E10 -> 20.540563 | L9: =L10*K9/K10 -> 24.117465 | M9: =M10*K9/K10 -> 22.795518 | N9: 0.09758 | O9: =O10*F9/F10 -> 16.222242 | Q9: =I$5*((J9/J$5)/(N9/N$5))*((O9/O$5)/(K9/K$5)) -> 2.39401e-13 | R9: =Q9/I9 -> 0.77980781 | S9: =R9/R$5 -> 0.8526981 | T9: =S9*I9 -> 2.6177832e-13 | U9: =I$5*((J9/J$5)/(N9/N$5))*((O9/O$5)/(L9/L$5)) -> 2.39401e-13 | V9: =U9/I9 -> 0.77980781 | W9: =V9/V$5 -> 0.8526981 | X9: =W9*I9 -> 2.6177832e-13 | Y9: =I$5*((J9/J$5)/(N9/N$5))*((O9/O$5)/(M9/M$5)) -> 2.39401e-13 | Z9: =Y9/I9 -> 0.77980781 | AA9: =Z9/Z$5 -> 0.8526981 | AB9: =AA9*I9 -> 2.6177832e-13 | AC9: =I$5*((J9/J$5)/(N9/N$5)) -> 3.6067358e-13 | AD9: =AC9/I9 -> 1.1748325 | AE9: =AD9/AD$5 -> 1.287492 | AF9: =AE9*I9 -> 3.9526006e-13
A10: =A11-1 -> 1939 | C10: 2.9e-13 | E10: 0.226 | F10: 0.179 | I10: 3.27e-13 | J10: 1.2158228e-14 | K10: =K11*E10/E11 -> 20.723961 | L10: =L11*K10/K11 -> 24.332799 | M10: =M11*K10/K11 -> 22.99905 | N10: 0.09619 | O10: =O11*F10/F11 -> 17.387912 | Q10: =I$5*((J10/J$5)/(N10/N$5))*((O10/O$5)/(K10/K$5)) -> 2.6210109e-13 | R10: =Q10/I10 -> 0.80153238 | S10: =R10/R$5 -> 0.8764533 | T10: =S10*I10 -> 2.8660023e-13 | U10: =I$5*((J10/J$5)/(N10/N$5))*((O10/O$5)/(L10/L$5)) -> 2.6210109e-13 | V10: =U10/I10 -> 0.80153238 | W10: =V10/V$5 -> 0.8764533 | X10: =W10*I10 -> 2.8660023e-13 | Y10: =I$5*((J10/J$5)/(N10/N$5))*((O10/O$5)/(M10/M$5)) -> 2.6210109e-13 | Z10: =Y10/I10 -> 0.80153238 | AA10: =Z10/Z$5 -> 0.8764533 | AB10: =AA10*I10 -> 2.8660023e-13 | AC10: =I$5*((J10/J$5)/(N10/N$5)) -> 3.7169016e-13 | AD10: =AC10/I10 -> 1.1366671 | AE10: =AD10/AD$5 -> 1.2456668 | AF10: =AE10*I10 -> 4.0733305e-13
A11: =A12-1 -> 1940 | C11: 3.33e-13 | E11: 0.22 | F11: 0.197 | I11: 3.36e-13 | J11: 1.243038e-14 | K11: =K12*E11/E12 -> 20.173767 | L11: =L12*K11/K12 -> 23.686796 | M11: =M12*K11/K12 -> 22.388455 | N11: 0.09689 | O11: =O12*F11/F12 -> 19.136417 | Q11: =I$5*((J11/J$5)/(N11/N$5))*((O11/O$5)/(K11/K$5)) -> 3.0076886e-13 | R11: =Q11/I11 -> 0.8951454 | S11: =R11/R$5 -> 0.97881654 | T11: =S11*I11 -> 3.2888236e-13 | U11: =I$5*((J11/J$5)/(N11/N$5))*((O11/O$5)/(L11/L$5)) -> 3.0076886e-13 | V11: =U11/I11 -> 0.8951454 | W11: =V11/V$5 -> 0.97881654 | X11: =W11*I11 -> 3.2888236e-13 | Y11: =I$5*((J11/J$5)/(N11/N$5))*((O11/O$5)/(M11/M$5)) -> 3.0076886e-13 | Z11: =Y11/I11 -> 0.8951454 | AA11: =Z11/Z$5 -> 0.97881654 | AB11: =AA11*I11 -> 3.2888236e-13 | AC11: =I$5*((J11/J$5)/(N11/N$5)) -> 3.7726468e-13 | AD11: =AC11/I11 -> 1.1228115 | AE11: =AD11/AD$5 -> 1.2304826 | AF11: =AE11*I11 -> 4.1344214e-13
A12: =A13-1 -> 1941 | C12: 3.58e-13 | E12: 0.206 | F12: 0.204 | I12: 3.36e-13 | J12: 1.2759494e-14 | K12: =K13*E12/E13 -> 18.889982 | L12: =L13*K12/K13 -> 22.179454 | M12: =M13*K12/K13 -> 20.963735 | N12: 0.1017 | O12: =O13*F12/F13 -> 19.816391 | Q12: =I$5*((J12/J$5)/(N12/N$5))*((O12/O$5)/(K12/K$5)) -> 3.2528146e-13 | R12: =Q12/I12 -> 0.96809959 | S12: =R12/R$5 -> 1.0585899 | T12: =S12*I12 -> 3.5568621e-13 | U12: =I$5*((J12/J$5)/(N12/N$5))*((O12/O$5)/(L12/L$5)) -> 3.2528146e-13 | V12: =U12/I12 -> 0.96809959 | W12: =V12/V$5 -> 1.0585899 | X12: =W12*I12 -> 3.5568621e-13 | Y12: =I$5*((J12/J$5)/(N12/N$5))*((O12/O$5)/(M12/M$5)) -> 3.2528146e-13 | Z12: =Y12/I12 -> 0.96809959 | AA12: =Z12/Z$5 -> 1.0585899 | AB12: =AA12*I12 -> 3.5568621e-13 | AC12: =I$5*((J12/J$5)/(N12/N$5)) -> 3.6893783e-13 | AD12: =AC12/I12 -> 1.0980293 | AE12: =AD12/AD$5 -> 1.2033238 | AF12: =AE12*I12 -> 4.043168e-13
A13: =A14-1 -> 1942 | C13: 3.56e-13 | E13: 0.196 | F13: 0.202 | I13: 3.36e-13 | J13: 1.3487342e-14 | K13: =K14*E13/E14 -> 17.972993 | L13: =L14*K13/K14 -> 21.102782 | M13: =M14*K13/K14 -> 19.946078 | N13: 0.1128 | O13: =O14*F13/F14 -> 19.622113 | Q13: =I$5*((J13/J$5)/(N13/N$5))*((O13/O$5)/(K13/K$5)) -> 3.2262383e-13 | R13: =Q13/I13 -> 0.96018996 | S13: =R13/R$5 -> 1.0499409 | T13: =S13*I13 -> 3.5278016e-13 | U13: =I$5*((J13/J$5)/(N13/N$5))*((O13/O$5)/(L13/L$5)) -> 3.2262383e-13 | V13: =U13/I13 -> 0.96018996 | W13: =V13/V$5 -> 1.0499409 | X13: =W13*I13 -> 3.5278016e-13 | Y13: =I$5*((J13/J$5)/(N13/N$5))*((O13/O$5)/(M13/M$5)) -> 3.2262383e-13 | Z13: =Y13/I13 -> 0.96018996 | AA13: =Z13/Z$5 -> 1.0499409 | AB13: =AA13*I13 -> 3.5278016e-13 | AC13: =I$5*((J13/J$5)/(N13/N$5)) -> 3.5160737e-13 | AD13: =AC13/I13 -> 1.0464505 | AE13: =AD13/AD$5 -> 1.1467989 | AF13: =AE13*I13 -> 3.8532445e-13
A14: =A15-1 -> 1943 | C14: 3.9e-13 | E14: 0.182 | F14: 0.215 | I14: 3.36e-13 | J14: 1.3632911e-14 | K14: =K15*E14/E15 -> 16.689208 | L14: =L15*K14/K15 -> 19.59544 | M14: =M15*K14/K15 -> 18.521359 | N14: 0.1197 | O14: =O15*F14/F15 -> 20.884922 | Q14: =I$5*((J14/J$5)/(N14/N$5))*((O14/O$5)/(K14/K$5)) -> 3.5224546e-13 | R14: =Q14/I14 -> 1.0483496 | S14: =R14/R$5 -> 1.1463411 | T14: =S14*I14 -> 3.8517059e-13 | U14: =I$5*((J14/J$5)/(N14/N$5))*((O14/O$5)/(L14/L$5)) -> 3.5224546e-13 | V14: =U14/I14 -> 1.0483496 | W14: =V14/V$5 -> 1.1463411 | X14: =W14*I14 -> 3.8517059e-13 | Y14: =I$5*((J14/J$5)/(N14/N$5))*((O14/O$5)/(M14/M$5)) -> 3.5224546e-13 | Z14: =Y14/I14 -> 1.0483496 | AA14: =Z14/Z$5 -> 1.1463411 | AB14: =AA14*I14 -> 3.8517059e-13 | AC14: =I$5*((J14/J$5)/(N14/N$5)) -> 3.3491544e-13 | AD14: =AC14/I14 -> 0.99677214 | AE14: =AD14/AD$5 -> 1.0923567 | AF14: =AE14*I14 -> 3.6703186e-13
A15: =A16-1 -> 1944 | C15: 4.1e-13 | E15: 0.188 | F15: 0.239 | I15: 3.36e-13 | J15: 1.3594937e-14 | K15: =K16*E15/E16 -> 17.239401 | L15: =L16*K15/K16 -> 20.241444 | M15: =M16*K15/K16 -> 19.131953 | N15: 0.1218 | O15: =O16*F15/F16 -> 23.216262 | Q15: =I$5*((J15/J$5)/(N15/N$5))*((O15/O$5)/(K15/K$5)) -> 3.7149573e-13 | R15: =Q15/I15 -> 1.1056421 | S15: =R15/R$5 -> 1.2089888 | T15: =S15*I15 -> 4.0622023e-13 | U15: =I$5*((J15/J$5)/(N15/N$5))*((O15/O$5)/(L15/L$5)) -> 3.7149573e-13 | V15: =U15/I15 -> 1.1056421 | W15: =V15/V$5 -> 1.2089888 | X15: =W15*I15 -> 4.0622023e-13 | Y15: =I$5*((J15/J$5)/(N15/N$5))*((O15/O$5)/(M15/M$5)) -> 3.7149573e-13 | Z15: =Y15/I15 -> 1.1056421 | AA15: =Z15/Z$5 -> 1.2089888 | AB15: =AA15*I15 -> 4.0622023e-13 | AC15: =I$5*((J15/J$5)/(N15/N$5)) -> 3.2822421e-13 | AD15: =AC15/I15 -> 0.97685776 | AE15: =AD15/AD$5 -> 1.0705327 | AF15: =AE15*I15 -> 3.5969898e-13
A16: =A17-1 -> 1945 | C16: 4.77e-13 | E16: 0.179 | F16: 0.227 | I16: 3.36e-13 | J16: 1.6278481e-14 | K16: =K17*E16/E17 -> 16.414111 | L16: =L17*K16/K17 -> 19.272438 | M16: =M17*K16/K17 -> 18.216061 | N16: 0.1246 | O16: =O17*F16/F17 -> 22.050592 | Q16: =I$5*((J16/J$5)/(N16/N$5))*((O16/O$5)/(K16/K$5)) -> 4.3376303e-13 | R16: =Q16/I16 -> 1.2909614 | S16: =R16/R$5 -> 1.4116303 | T16: =S16*I16 -> 4.7430778e-13 | U16: =I$5*((J16/J$5)/(N16/N$5))*((O16/O$5)/(L16/L$5)) -> 4.3376303e-13 | V16: =U16/I16 -> 1.2909614 | W16: =V16/V$5 -> 1.4116303 | X16: =W16*I16 -> 4.7430778e-13 | Y16: =I$5*((J16/J$5)/(N16/N$5))*((O16/O$5)/(M16/M$5)) -> 4.3376303e-13 | Z16: =Y16/I16 -> 1.2909614 | AA16: =Z16/Z$5 -> 1.4116303 | AB16: =AA16*I16 -> 4.7430778e-13 | AC16: =I$5*((J16/J$5)/(N16/N$5)) -> 3.8418158e-13 | AD16: =AC16/I16 -> 1.1433976 | AE16: =AD16/AD$5 -> 1.2530427 | AF16: =AE16*I16 -> 4.2102234e-13
A17: =A18-1 -> 1946 | C17: 4.36e-13 | E17: 0.188 | F17: 0.2 | I17: 3.36e-13 | J17: 1.9151899e-14 | K17: =K18*E17/E18 -> 17.239401 | L17: =L18*K17/K18 -> 20.241444 | M17: =M18*K17/K18 -> 19.131953 | N17: 0.1349 | O17: =O18*F17/F18 -> 19.427834 | Q17: =I$5*((J17/J$5)/(N17/N$5))*((O17/O$5)/(K17/K$5)) -> 3.9541752e-13 | R17: =Q17/I17 -> 1.1768379 | S17: =R17/R$5 -> 1.2868394 | T17: =S17*I17 -> 4.3237803e-13 | U17: =I$5*((J17/J$5)/(N17/N$5))*((O17/O$5)/(L17/L$5)) -> 3.9541752e-13 | V17: =U17/I17 -> 1.1768379 | W17: =V17/V$5 -> 1.2868394 | X17: =W17*I17 -> 4.3237803e-13 | Y17: =I$5*((J17/J$5)/(N17/N$5))*((O17/O$5)/(M17/M$5)) -> 3.9541752e-13 | Z17: =Y17/I17 -> 1.1768379 | AA17: =Z17/Z$5 -> 1.2868394 | AB17: =AA17*I17 -> 4.3237803e-13 | AC17: =I$5*((J17/J$5)/(N17/N$5)) -> 4.1748473e-13 | AD17: =AC17/I17 -> 1.2425141 | AE17: =AD17/AD$5 -> 1.3616639 | AF17: =AE17*I17 -> 4.5751906e-13
A18: =A19-1 -> 1947 | C18: 4.19e-13 | E18: 0.205 | F18: 0.211 | I18: 3.36e-13 | J18: 2.1746835e-14 | K18: =K19*E18/E19 -> 18.798283 | L18: =L19*K18/K19 -> 22.071787 | M18: =M19*K18/K19 -> 20.86197 | N18: 0.1543 | O18: =O19*F18/F19 -> 20.496365 | Q18: =I$5*((J18/J$5)/(N18/N$5))*((O18/O$5)/(K18/K$5)) -> 3.797892e-13 | R18: =Q18/I18 -> 1.130325 | S18: =R18/R$5 -> 1.2359789 | T18: =S18*I18 -> 4.152889e-13 | U18: =I$5*((J18/J$5)/(N18/N$5))*((O18/O$5)/(L18/L$5)) -> 3.797892e-13 | V18: =U18/I18 -> 1.130325 | W18: =V18/V$5 -> 1.2359789 | X18: =W18*I18 -> 4.152889e-13 | Y18: =I$5*((J18/J$5)/(N18/N$5))*((O18/O$5)/(M18/M$5)) -> 3.797892e-13 | Z18: =Y18/I18 -> 1.130325 | AA18: =Z18/Z$5 -> 1.2359789 | AB18: =AA18*I18 -> 4.152889e-13 | AC18: =I$5*((J18/J$5)/(N18/N$5)) -> 4.1444876e-13 | AD18: =AC18/I18 -> 1.2334785 | AE18: =AD18/AD$5 -> 1.3517618 | AF18: =AE18*I18 -> 4.5419196e-13
... A60: =A61-1 -> 1989 | C60: 0.0297 | E60: 0.585 | F60: 0.739 | I60: 0.0394 | J60: 0.0069873418 | K60: =K61*E60/E61 -> 53.643882 | L60: =L61*K60/K61 -> 62.985343 | M60: =M61*K60/K61 -> 59.532938 | N60: 0.8581 | O60: =O61*F60/F61 -> 71.785848 | Q60: =I$5*((J60/J$5)/(N60/N$5))*((O60/O$5)/(K60/K$5)) -> 0.026930631 | R60: =Q60/I60 -> 0.68351856 | S60: =R60/R$5 -> 0.74740849 | T60: =S60*I60 -> 0.029447894 | U60: =I$5*((J60/J$5)/(N60/N$5))*((O60/O$5)/(L60/L$5)) -> 0.026930631 | V60: =U60/I60 -> 0.68351856 | W60: =V60/V$5 -> 0.74740849 | X60: =W60*I60 -> 0.029447894 | Y60: =I$5*((J60/J$5)/(N60/N$5))*((O60/O$5)/(M60/M$5)) -> 0.026930631 | Z60: =Y60/I60 -> 0.68351856 | AA60: =Z60/Z$5 -> 0.74740849 | AB60: =AA60*I60 -> 0.029447894 | AC60: =I$5*((J60/J$5)/(N60/N$5)) -> 0.023944997 | AD60: =AC60/I60 -> 0.60774104 | AE60: =AD60/AD$5 -> 0.66601984 | AF60: =AE60*I60 -> 0.026241181
A61: 1990 | C61: 0.733 | E61: 0.559 | F61: 0.761 | I61: 0.449 | J61: 0.16858592 | K61: =K62*E61/E62 -> 51.259709 | L61: =L62*K61/K62 -> 60.185995 | M61: =M62*K61/K62 -> 56.88703 | N61: 0.9045 | O61: 73.92291 | Q61: =I$5*((J61/J$5)/(N61/N$5))*((O61/O$5)/(K61/K$5)) -> 0.66430794 | R61: =Q61/I61 -> 1.4795277 | S61: =R61/R$5 -> 1.6178223 | T61: =S61*I61 -> 0.72640221 | U61: =I$5*((J61/J$5)/(N61/N$5))*((O61/O$5)/(L61/L$5)) -> 0.66430794 | V61: =U61/I61 -> 1.4795277 | W61: =V61/V$5 -> 1.6178223 | X61: =W61*I61 -> 0.72640221 | Y61: =I$5*((J61/J$5)/(N61/N$5))*((O61/O$5)/(M61/M$5)) -> 0.66430794 | Z61: =Y61/I61 -> 1.4795277 | AA61: =Z61/Z$5 -> 1.6178223 | AB61: =AA61*I61 -> 0.72640221 | AC61: =I$5*((J61/J$5)/(N61/N$5)) -> 0.54809195 | AD61: =AC61/I61 -> 1.2206948 | AE61: =AD61/AD$5 -> 1.3377522 | AF61: =AE61*I61 -> 0.60065075
A62: 1991 | B62: 0.95 | C62: 1.69 | D62: 1.59 | E62: 0.647 | I62: 0.95 | J62: 0.45800023 | K62: =K63*E62/E63 -> 59.329216 | L62: =L63*K62/K63 -> 69.660713 | M62: =M63*K62/K63 -> 65.842412 | N62: 0.9426 | O62: 75.612484 | Q62: =I$5*((J62/J$5)/(N62/N$5))*((O62/O$5)/(K62/K$5)) -> 1.5304423 | R62: =Q62/I62 -> 1.6109919 | S62: =R62/R$5 -> 1.7615747 | T62: =S62*I62 -> 1.673496 | U62: =I$5*((J62/J$5)/(N62/N$5))*((O62/O$5)/(L62/L$5)) -> 1.5304423 | V62: =U62/I62 -> 1.6109919 | W62: =V62/V$5 -> 1.7615747 | X62: =W62*I62 -> 1.673496 | Y62: =I$5*((J62/J$5)/(N62/N$5))*((O62/O$5)/(M62/M$5)) -> 1.5304423 | Z62: =Y62/I62 -> 1.6109919 | AA62: =Z62/Z$5 -> 1.7615747 | AB62: =AA62*I62 -> 1.673496 | AC62: =I$5*((J62/J$5)/(N62/N$5)) -> 1.4288247 | AD62: =AC62/I62 -> 1.504026 | AE62: =AD62/AD$5 -> 1.6482533 | AF62: =AE62*I62 -> 1.5658406
A63: 1992 | B63: 0.99 | C63: 1.9 | D63: 1.93 | E63: 0.737 | I63: 0.99 | J63: 0.57204205 | K63: =K64*E63/E64 -> 67.582121 | L63: =L64*K63/K64 -> 79.350766 | M63: =M64*K63/K64 -> 75.001325 | N63: 0.9709 | O63: 79.605043 | Q63: =I$5*((J63/J$5)/(N63/N$5))*((O63/O$5)/(K63/K$5)) -> 1.715205 | R63: =Q63/I63 -> 1.7325303 | S63: =R63/R$5 -> 1.8944735 | T63: =S63*I63 -> 1.8755288 | U63: =I$5*((J63/J$5)/(N63/N$5))*((O63/O$5)/(L63/L$5)) -> 1.715205 | V63: =U63/I63 -> 1.7325303 | W63: =V63/V$5 -> 1.8944735 | X63: =W63*I63 -> 1.8755288 | Y63: =I$5*((J63/J$5)/(N63/N$5))*((O63/O$5)/(M63/M$5)) -> 1.715205 | Z63: =Y63/I63 -> 1.7325303 | AA63: =Z63/Z$5 -> 1.8944735 | AB63: =AA63*I63 -> 1.8755288 | AC63: =I$5*((J63/J$5)/(N63/N$5)) -> 1.7325834 | AD63: =AC63/I63 -> 1.7500843 | AE63: =AD63/AD$5 -> 1.9179071 | AF63: =AE63*I63 -> 1.898728
A64: 1993 | B64: 0.99 | C64: 1.97 | D64: 2.07 | E64: 0.785 | I64: 0.99 | J64: 0.63274437 | K64: 71.98367 | L64: 84.518794 | M64: 79.886079 | N64: 1 | O64: 82.204164 | Q64: =I$5*((J64/J$5)/(N64/N$5))*((O64/O$5)/(K64/K$5)) -> 1.7858375 | R64: =Q64/I64 -> 1.8038762 | S64: =R64/R$5 -> 1.9724884 | T64: =S64*I64 -> 1.9527635 | U64: =I$5*((J64/J$5)/(N64/N$5))*((O64/O$5)/(L64/L$5)) -> 1.7858375 | V64: =U64/I64 -> 1.8038762 | W64: =V64/V$5 -> 1.9724884 | X64: =W64*I64 -> 1.9527635 | Y64: =I$5*((J64/J$5)/(N64/N$5))*((O64/O$5)/(M64/M$5)) -> 1.7858375 | Z64: =Y64/I64 -> 1.8038762 | AA64: =Z64/Z$5 -> 1.9724884 | AB64: =AA64*I64 -> 1.9527635 | AC64: =I$5*((J64/J$5)/(N64/N$5)) -> 1.8606685 | AD64: =AC64/I64 -> 1.8794631 | AE64: =AD64/AD$5 -> 2.0596925 | AF64: =AE64*I64 -> 2.0390956
A65: 1994 | B65: 1 | C65: 1.98 | D65: 2.1 | I65: 1 | J65: 0.65917624 | K65: 82.547503 | L65: 99.06571 | M65: 91.674682 | N65: 1.026 | O65: 85.320435 | Q65: =I$5*((J65/J$5)/(N65/N$5))*((O65/O$5)/(K65/K$5)) -> 1.6411834 | R65: =Q65/I65 -> 1.6411834 | S65: =R65/R$5 -> 1.7945883 | T65: =S65*I65 -> 1.7945883 | U65: =I$5*((J65/J$5)/(N65/N$5))*((O65/O$5)/(L65/L$5)) -> 1.6056726 | V65: =U65/I65 -> 1.6056726 | W65: =V65/V$5 -> 1.7557582 | X65: =W65*I65 -> 1.7557582 | Y65: =I$5*((J65/J$5)/(N65/N$5))*((O65/O$5)/(M65/M$5)) -> 1.6400186 | Z65: =Y65/I65 -> 1.6400186 | AA65: =Z65/Z$5 -> 1.7933146 | AB65: =AA65*I65 -> 1.7933146 | AC65: =I$5*((J65/J$5)/(N65/N$5)) -> 1.8892737 | AD65: =AC65/I65 -> 1.8892737 | AE65: =AD65/AD$5 -> 2.070444 | AF65: =AE65*I65 -> 2.070444
A66: 1995 | B66: 0.99 | C66: 2.07 | D66: 2.11 | I66: 0.99 | J66: 0.68143068 | K66: 84.240539 | L66: 94.003401 | M66: 86.088607 | N66: 1.055 | O66: 88.411072 | Q66: =I$5*((J66/J$5)/(N66/N$5))*((O66/O$5)/(K66/K$5)) -> 1.6753616 | R66: =Q66/I66 -> 1.6922844 | S66: =R66/R$5 -> 1.8504658 | T66: =S66*I66 -> 1.8319612 | U66: =I$5*((J66/J$5)/(N66/N$5))*((O66/O$5)/(L66/L$5)) -> 1.7628097 | V66: =U66/I66 -> 1.7806158 | W66: =V66/V$5 -> 1.9470538 | X66: =W66*I66 -> 1.9275832 | Y66: =I$5*((J66/J$5)/(N66/N$5))*((O66/O$5)/(M66/M$5)) -> 1.8193704 | Z66: =Y66/I66 -> 1.8377479 | AA66: =Z66/Z$5 -> 2.0095261 | AB66: =AA66*I66 -> 1.9894308 | AC66: =I$5*((J66/J$5)/(N66/N$5)) -> 1.8993715 | AD66: =AC66/I66 -> 1.9185571 | AE66: =AD66/AD$5 -> 2.1025355 | AF66: =AE66*I66 -> 2.0815101
A67: 1996 | B67: 1 | C67: 1.89 | D67: 2.06 | I67: 1 | J67: 0.68249151 | K67: 94.110664 | L67: 98.592739 | M67: 93.064174 | N67: 1.086 | O67: 93.284375 | Q67: =I$5*((J67/J$5)/(N67/N$5))*((O67/O$5)/(K67/K$5)) -> 1.5395412 | R67: =Q67/I67 -> 1.5395412 | S67: =R67/R$5 -> 1.6834453 | T67: =S67*I67 -> 1.6834453 | U67: =I$5*((J67/J$5)/(N67/N$5))*((O67/O$5)/(L67/L$5)) -> 1.7254585 | V67: =U67/I67 -> 1.7254585 | W67: =V67/V$5 -> 1.8867408 | X67: =W67*I67 -> 1.8867408 | Y67: =I$5*((J67/J$5)/(N67/N$5))*((O67/O$5)/(M67/M$5)) -> 1.7277653 | Z67: =Y67/I67 -> 1.7277653 | AA67: =Z67/Z$5 -> 1.8892631 | AB67: =AA67*I67 -> 1.8892631 | AC67: =I$5*((J67/J$5)/(N67/N$5)) -> 1.8480262 | AD67: =AC67/I67 -> 1.8480262 | AE67: =AD67/AD$5 -> 2.0252411 | AF67: =AE67*I67 -> 2.0252411
A68: 1997 | B68: 1 | C68: 1.79 | D68: 2.02 | I68: 1 | J68: 0.68609908 | K68: 100 | L68: 100 | M68: 100 | N68: 1.111 | O68: 100 | Q68: =I$5*((J68/J$5)/(N68/N$5))*((O68/O$5)/(K68/K$5)) -> 1.5262532 | R68: =Q68/I68 -> 1.5262532 | S68: =R68/R$5 -> 1.6689153 | T68: =S68*I68 -> 1.6689153 | U68: =I$5*((J68/J$5)/(N68/N$5))*((O68/O$5)/(L68/L$5)) -> 1.7920325 | V68: =U68/I68 -> 1.7920325 | W68: =V68/V$5 -> 1.9595376 | X68: =W68*I68 -> 1.9595376 | Y68: =I$5*((J68/J$5)/(N68/N$5))*((O68/O$5)/(M68/M$5)) -> 1.6938062 | Z68: =Y68/I68 -> 1.6938062 | AA68: =Z68/Z$5 -> 1.8521298 | AB68: =AA68*I68 -> 1.8521298 | AC68: =I$5*((J68/J$5)/(N68/N$5)) -> 1.8159901 | AD68: =AC68/I68 -> 1.8159901 | AE68: =AD68/AD$5 -> 1.9901329 | AF68: =AE68*I68 -> 1.9901329
A69: 1998 | B69: 1 | C69: 1.8 | D69: 2.01 | I69: 1 | J69: 0.6924432 | K69: 97.080398 | L69: 105.40486 | M69: 104.37148 | N69: 1.128 | O69: 106.27677 | Q69: =I$5*((J69/J$5)/(N69/N$5))*((O69/O$5)/(K69/K$5)) -> 1.6608701 | R69: =Q69/I69 -> 1.6608701 | S69: =R69/R$5 -> 1.8161151 | T69: =S69*I69 -> 1.8161151 | U69: =I$5*((J69/J$5)/(N69/N$5))*((O69/O$5)/(L69/L$5)) -> 1.7960808 | V69: =U69/I69 -> 1.7960808 | W69: =V69/V$5 -> 1.9639643 | X69: =W69*I69 -> 1.9639643 | Y69: =I$5*((J69/J$5)/(N69/N$5))*((O69/O$5)/(M69/M$5)) -> 1.7144408 | Z69: =Y69/I69 -> 1.7144408 | AA69: =Z69/Z$5 -> 1.8746932 | AB69: =AA69*I69 -> 1.8746932 | AC69: =I$5*((J69/J$5)/(N69/N$5)) -> 1.8051602 | AD69: =AC69/I69 -> 1.8051602 | AE69: =AD69/AD$5 -> 1.9782645 | AF69: =AE69*I69 -> 1.9782645
A70: 1999 | B70: 1 | C70: 1.85 | D70: 1.94 | I70: 1 | J70: 0.68436463 | K70: 94.596914 | L70: 96.727279 | M70: 100.86458 | N70: 1.153 | O70: 113.60723 | Q70: =I$5*((J70/J$5)/(N70/N$5))*((O70/O$5)/(K70/K$5)) -> 1.7617369 | R70: =Q70/I70 -> 1.7617369 | S70: =R70/R$5 -> 1.9264102 | T70: =S70*I70 -> 1.9264102 | U70: =I$5*((J70/J$5)/(N70/N$5))*((O70/O$5)/(L70/L$5)) -> 2.0229649 | V70: =U70/I70 -> 2.0229649 | W70: =V70/V$5 -> 2.2120557 | X70: =W70*I70 -> 2.2120557 | Y70: =I$5*((J70/J$5)/(N70/N$5))*((O70/O$5)/(M70/M$5)) -> 1.83365 | Z70: =Y70/I70 -> 1.83365 | AA70: =Z70/Z$5 -> 2.0050452 | AB70: =AA70*I70 -> 2.0050452 | AC70: =I$5*((J70/J$5)/(N70/N$5)) -> 1.745416 | AD70: =AC70/I70 -> 1.745416 | AE70: =AD70/AD$5 -> 1.9127911 | AF70: =AE70*I70 -> 1.9127911
A71: 2000 | B71: 1 | C71: 1.74 | D71: 1.86 | I71: 1 | J71: 0.67793771 | K71: 94.14454 | L71: 105.26128 | M71: 109.76361 | N71: 1.192 | O71: 119.46064 | Q71: =I$5*((J71/J$5)/(N71/N$5))*((O71/O$5)/(K71/K$5)) -> 1.7835983 | R71: =Q71/I71 -> 1.7835983 | S71: =R71/R$5 -> 1.950315 | T71: =S71*I71 -> 1.950315 | U71: =I$5*((J71/J$5)/(N71/N$5))*((O71/O$5)/(L71/L$5)) -> 1.8730218 | V71: =U71/I71 -> 1.8730218 | W71: =V71/V$5 -> 2.0480971 | X71: =W71*I71 -> 2.0480971 | Y71: =I$5*((J71/J$5)/(N71/N$5))*((O71/O$5)/(M71/M$5)) -> 1.697739 | Z71: =Y71/I71 -> 1.697739 | AA71: =Z71/Z$5 -> 1.8564302 | AB71: =AA71*I71 -> 1.8564302 | AC71: =I$5*((J71/J$5)/(N71/N$5)) -> 1.6724542 | AD71: =AC71/I71 -> 1.6724542 | AE71: =AD71/AD$5 -> 1.8328327 | AF71: =AE71*I71 -> 1.8328327
A72: 2001 | B72: 1 | C72: 1.79 | D72: 1.79 | I72: 1 | J72: 0.67071426 | K72: 88.349002 | L72: 105.24287 | M72: 108.941 | N72: 1.226 | O72: 122.78976 | Q72: =I$5*((J72/J$5)/(N72/N$5))*((O72/O$5)/(K72/K$5)) -> 1.8791496 | R72: =Q72/I72 -> 1.8791496 | S72: =R72/R$5 -> 2.0547977 | T72: =S72*I72 -> 2.0547977 | U72: =I$5*((J72/J$5)/(N72/N$5))*((O72/O$5)/(L72/L$5)) -> 1.8522076 | V72: =U72/I72 -> 1.8522076 | W72: =V72/V$5 -> 2.0253373 | X72: =W72*I72 -> 2.0253373 | Y72: =I$5*((J72/J$5)/(N72/N$5))*((O72/O$5)/(M72/M$5)) -> 1.6912537 | Z72: =Y72/I72 -> 1.6912537 | AA72: =Z72/Z$5 -> 1.8493388 | AB72: =AA72*I72 -> 1.8493388 | AC72: =I$5*((J72/J$5)/(N72/N$5)) -> 1.6087471 | AD72: =AC72/I72 -> 1.6087471 | AE72: =AD72/AD$5 -> 1.7630165 | AF72: =AE72*I72 -> 1.7630165
A73: 2002 | B73: 3.14 | C73: 2.4 | D73: 2.22 | I73: 3.14 | J73: 0.84421828 | K73: 79.988317 | L73: 131.5327 | M73: 133.80529 | N73: 1.245 | O73: 134.07299 | Q73: =I$5*((J73/J$5)/(N73/N$5))*((O73/O$5)/(K73/K$5)) -> 2.8090143 | R73: =Q73/I73 -> 0.89459053 | S73: =R73/R$5 -> 0.9782098 | T73: =S73*I73 -> 3.0715788 | U73: =I$5*((J73/J$5)/(N73/N$5))*((O73/O$5)/(L73/L$5)) -> 2.0057004 | V73: =U73/I73 -> 0.63875809 | W73: =V73/V$5 -> 0.69846416 | X73: =W73*I73 -> 2.1931775 | Y73: =I$5*((J73/J$5)/(N73/N$5))*((O73/O$5)/(M73/M$5)) -> 1.8635642 | Z73: =Y73/I73 -> 0.59349177 | AA73: =Z73/Z$5 -> 0.6489667 | AB73: =AA73*I73 -> 2.0377554 | AC73: =I$5*((J73/J$5)/(N73/N$5)) -> 1.9940044 | AD73: =AC73/I73 -> 0.63503324 | AE73: =AD73/AD$5 -> 0.69592919 | AF73: =AE73*I73 -> 2.1852177
A74: 2003 | B74: 2.93 | C74: 2.53 | D74: 2.46 | I74: 2.93 | J74: 0.95770776 | K74: 82.662494 | L74: 128.7609 | M74: 140.48616 | N74: 1.273 | O74: 143.95953 | Q74: =I$5*((J74/J$5)/(N74/N$5))*((O74/O$5)/(K74/K$5)) -> 3.2381005 | R74: =Q74/I74 -> 1.1051538 | S74: =R74/R$5 -> 1.2084548 | T74: =S74*I74 -> 3.5407726 | U74: =I$5*((J74/J$5)/(N74/N$5))*((O74/O$5)/(L74/L$5)) -> 2.4408108 | V74: =U74/I74 -> 0.83304123 | W74: =V74/V$5 -> 0.91090736 | X74: =W74*I74 -> 2.6689586 | Y74: =I$5*((J74/J$5)/(N74/N$5))*((O74/O$5)/(M74/M$5)) -> 2.1144743 | Z74: =Y74/I74 -> 0.72166357 | AA74: =Z74/Z$5 -> 0.789119 | AB74: =AA74*I74 -> 2.3121187 | AC74: =I$5*((J74/J$5)/(N74/N$5)) -> 2.2123066 | AD74: =AC74/I74 -> 0.75505343 | AE74: =AD74/AD$5 -> 0.82745862 | AF74: =AE74*I74 -> 2.4244537
A75: 2004 | B75: 2.93 | C75: 2.64 | D75: 2.5 | I75: 2.93 | J75: 1 | K75: 90.338934 | L75: 146.52488 | M75: 153.99498 | N75: 1.307 | O75: 150.40394 | Q75: =I$5*((J75/J$5)/(N75/N$5))*((O75/O$5)/(K75/K$5)) -> 3.1482011 | R75: =Q75/I75 -> 1.0744714 | S75: =R75/R$5 -> 1.1749045 | T75: =S75*I75 -> 3.4424701 | U75: =I$5*((J75/J$5)/(N75/N$5))*((O75/O$5)/(L75/L$5)) -> 2.2790053 | V75: =U75/I75 -> 0.77781752 | W75: =V75/V$5 -> 0.85052177 | X75: =W75*I75 -> 2.4920288 | Y75: =I$5*((J75/J$5)/(N75/N$5))*((O75/O$5)/(M75/M$5)) -> 2.0495946 | Z75: =Y75/I75 -> 0.69952034 | AA75: =Z75/Z$5 -> 0.76490599 | AB75: =AA75*I75 -> 2.2411746 | AC75: =I$5*((J75/J$5)/(N75/N$5)) -> 2.2499099 | AD75: =AC75/I75 -> 0.76788732 | AE75: =AD75/AD$5 -> 0.8415232 | AF75: =AE75*I75 -> 2.465663
A76: =A75+1 -> 2005 | I76: 2.9284167 | J76: 1.096424 | K76: 88.878478 | L76: 142.18761 | M76: 154.65523 | N76: 1.3518099 | O76: 157.15477 | Q76: =I$5*((J76/J$5)/(N76/N$5))*((O76/O$5)/(K76/K$5)) -> 3.5444405 | R76: =Q76/I76 -> 1.2103607 | S76: =R76/R$5 -> 1.3234957 | T76: =S76*I76 -> 3.8757468 | U76: =I$5*((J76/J$5)/(N76/N$5))*((O76/O$5)/(L76/L$5)) -> 2.6013683 | V76: =U76/I76 -> 0.88831904 | W76: =V76/V$5 -> 0.9713521 | X76: =W76*I76 -> 2.8445237 | Y76: =I$5*((J76/J$5)/(N76/N$5))*((O76/O$5)/(M76/M$5)) -> 2.260564 | Z76: =Y76/I76 -> 0.77194068 | AA76: =Z76/Z$5 -> 0.84409561 | AB76: =AA76*I76 -> 2.4718636 | AC76: =I$5*((J76/J$5)/(N76/N$5)) -> 2.3850837 | AD76: =AC76/I76 -> 0.81446186 | AE76: =AD76/AD$5 -> 0.89256396 | AF76: =AE76*I76 -> 2.6137992
A77: =A76+1 -> 2006 | I77: 3.07775 | J77: 1.2089396 | K77: 91.964433 | L77: 144.27253 | M77: 156.92362 | N77: 1.3954826 | O77: 160.29438 | Q77: =I$5*((J77/J$5)/(N77/N$5))*((O77/O$5)/(K77/K$5)) -> 3.7319205 | R77: =Q77/I77 -> 1.2125483 | S77: =R77/R$5 -> 1.3258877 | T77: =S77*I77 -> 4.080751 | U77: =I$5*((J77/J$5)/(N77/N$5))*((O77/O$5)/(L77/L$5)) -> 2.7931094 | V77: =U77/I77 -> 0.90751666 | W77: =V77/V$5 -> 0.99234416 | X77: =W77*I77 -> 3.0541872 | Y77: =I$5*((J77/J$5)/(N77/N$5))*((O77/O$5)/(M77/M$5)) -> 2.427175 | Z77: =Y77/I77 -> 0.78861993 | AA77: =Z77/Z$5 -> 0.8623339 | AB77: =AA77*I77 -> 2.6540482 | AC77: =I$5*((J77/J$5)/(N77/N$5)) -> 2.5475393 | AD77: =AC77/I77 -> 0.82772782 | AE77: =AD77/AD$5 -> 0.90710205 | AF77: =AE77*I77 -> 2.7918333
A78: =A77+1 -> 2007 | I78: 3.1191667 | J78: 1.4301886 | K78: 100.03275 | L78: 154.87346 | M78: 168.45438 | N78: 1.4352526 | O78: 168.20073 | Q78: =I$5*((J78/J$5)/(N78/N$5))*((O78/O$5)/(K78/K$5)) -> 4.1409928 | R78: =Q78/I78 -> 1.3275959 | S78: =R78/R$5 -> 1.4516891 | T78: =S78*I78 -> 4.5280601 | U78: =I$5*((J78/J$5)/(N78/N$5))*((O78/O$5)/(L78/L$5)) -> 3.1404288 | V78: =U78/I78 -> 1.0068166 | W78: =V78/V$5 -> 1.1009259 | X78: =W78*I78 -> 3.4339713 | Y78: =I$5*((J78/J$5)/(N78/N$5))*((O78/O$5)/(M78/M$5)) -> 2.728987 | Z78: =Y78/I78 -> 0.87490902 | AA78: =Z78/Z$5 -> 0.95668861 | AB78: =AA78*I78 -> 2.9840712 | AC78: =I$5*((J78/J$5)/(N78/N$5)) -> 2.9302568 | AD78: =AC78/I78 -> 0.93943577 | AE78: =AD78/AD$5 -> 1.0295221 | AF78: =AE78*I78 -> 3.2112511
A79: =A78+1 -> 2008 | I79: 3.1831667 | J79: 1.8171998 | K79: 98.958019 | L79: 155.51686 | M79: 169.15405 | N79: 1.490271 | O79: 166.28774 | Q79: =I$5*((J79/J$5)/(N79/N$5))*((O79/O$5)/(K79/K$5)) -> 5.0640794 | R79: =Q79/I79 -> 1.5908936 | S79: =R79/R$5 -> 1.7395978 | T79: =S79*I79 -> 5.5374296 | U79: =I$5*((J79/J$5)/(N79/N$5))*((O79/O$5)/(L79/L$5)) -> 3.7834964 | V79: =U79/I79 -> 1.1885951 | W79: =V79/V$5 -> 1.2996956 | X79: =W79*I79 -> 4.1371478 | Y79: =I$5*((J79/J$5)/(N79/N$5))*((O79/O$5)/(M79/M$5)) -> 3.2878062 | Z79: =Y79/I79 -> 1.0328728 | AA79: =Z79/Z$5 -> 1.1294176 | AB79: =AA79*I79 -> 3.5951244 | AC79: =I$5*((J79/J$5)/(N79/N$5)) -> 3.5857347 | AD79: =AC79/I79 -> 1.1264678 | AE79: =AD79/AD$5 -> 1.2344894 | AF79: =AE79*I79 -> 3.9295855
A80: =A79+1 -> 2009 | I80: 3.75 | J80: 2.0822574 | K80: 91.364301 | L80: 136.68539 | M80: 154.23329 | N80: 1.4851002 | O80: 166.18724 | Q80: =I$5*((J80/J$5)/(N80/N$5))*((O80/O$5)/(K80/K$5)) -> 6.3030912 | R80: =Q80/I80 -> 1.6808243 | S80: =R80/R$5 -> 1.8379345 | T80: =S80*I80 -> 6.8922545 | U80: =I$5*((J80/J$5)/(N80/N$5))*((O80/O$5)/(L80/L$5)) -> 4.9468341 | V80: =U80/I80 -> 1.3191558 | W80: =V80/V$5 -> 1.44246 | X80: =W80*I80 -> 5.4092252 | Y80: =I$5*((J80/J$5)/(N80/N$5))*((O80/O$5)/(M80/M$5)) -> 4.1437078 | Z80: =Y80/I80 -> 1.1049887 | AA80: =Z80/Z$5 -> 1.2082744 | AB80: =AA80*I80 -> 4.5310289 | AC80: =I$5*((J80/J$5)/(N80/N$5)) -> 4.1230572 | AD80: =AC80/I80 -> 1.0994819 | AE80: =AD80/AD$5 -> 1.2049158 | AF80: =AE80*I80 -> 4.5184341
A81: =A80+1 -> 2010 | I81: 3.89 | J81: 2.5630419 | K81: 110.38261 | L81: 145.83817 | M81: 161.59825 | N81: 1.5094977 | O81: 182.56289 | Q81: =I$5*((J81/J$5)/(N81/N$5))*((O81/O$5)/(K81/K$5)) -> 6.9404705 | R81: =Q81/I81 -> 1.7841827 | S81: =R81/R$5 -> 1.950954 | T81: =S81*I81 -> 7.589211 | U81: =I$5*((J81/J$5)/(N81/N$5))*((O81/O$5)/(L81/L$5)) -> 6.167905 | V81: =U81/I81 -> 1.5855797 | W81: =V81/V$5 -> 1.7337872 | X81: =W81*I81 -> 6.7444321 | Y81: =I$5*((J81/J$5)/(N81/N$5))*((O81/O$5)/(M81/M$5)) -> 5.2612633 | Z81: =Y81/I81 -> 1.3525098 | AA81: =Z81/Z$5 -> 1.4789318 | AB81: =AA81*I81 -> 5.7530447 | AC81: =I$5*((J81/J$5)/(N81/N$5)) -> 4.9930275 | AD81: =AC81/I81 -> 1.2835546 | AE81: =AD81/AD$5 -> 1.40664 | AF81: =AE81*I81 -> 5.4718294
A82: =A81+1 -> 2011 | I82: 4.11 | J82: 3.1636717 | K82: 111.80629 | L82: 150.39454 | M82: 164.73475 | N82: 1.5570928 | O82: 185.0506 | Q82: =I$5*((J82/J$5)/(N82/N$5))*((O82/O$5)/(K82/K$5)) -> 8.3110328 | R82: =Q82/I82 -> 2.0221491 | S82: =R82/R$5 -> 2.2111636 | T82: =S82*I82 -> 9.0878826 | U82: =I$5*((J82/J$5)/(N82/N$5))*((O82/O$5)/(L82/L$5)) -> 7.2545159 | V82: =U82/I82 -> 1.765089 | W82: =V82/V$5 -> 1.9300756 | X82: =W82*I82 -> 7.9326109 | Y82: =I$5*((J82/J$5)/(N82/N$5))*((O82/O$5)/(M82/M$5)) -> 6.2599826 | Z82: =Y82/I82 -> 1.5231101 | AA82: =Z82/Z$5 -> 1.6654785 | AB82: =AA82*I82 -> 6.8451164 | AC82: =I$5*((J82/J$5)/(N82/N$5)) -> 5.9747207 | AD82: =AC82/I82 -> 1.4537033 | AE82: =AD82/AD$5 -> 1.5931049 | AF82: =AE82*I82 -> 6.5476613
...

Sheet Corporaciones
B1: JIC | N1: Propias | V1: Propias | AM1: Relación TCP con JIC
E2: IPT Arg JIC | F2: IPT USA | G2: PBI pm | H2: PBI pm | J2: Empleo Total | L2: IPT | O2: ARG | S2: USA | T2: USA | V2: IPC + IPI Total | Z2: IPC + ENGE ind Sin imp | AD2: IPC + ENGE ind con imp | AH2: IPC | AM2: IPI Total | AN2: ENGE Sin imp | AO2: Enge con imp
B3: TCC | C3: Paridad por ipi + ipc | D3: Paridad por IPC | G3: 1993 | H3: 1993 | J3: 36-73 jic / 74 propias | L3: Total | N3: TCC | O3: IPC | P3: IPT Arg | Q3: IPT ENGE | R3: IPT ENGE | S3: IPC | T3: Nonfinancial corporate sector | V3: TCP arb | W3: TCP arb/TCC | X3: Sobrevaluación | Y3: TCP | Z3: TCP arb | AA3: TCP arb/TCC | AB3: Sobrevaluación | AC3: TCP | AD3: TCP arb | AE3: TCP arb/TCC | AF3: Sobrevaluación | AG3: TCP | AH3: TCP arb | AI3: TCP arb/TCC | AJ3: Sobrevaluación | AK3: TCP
G4: Base 1993 | H4: empalme base 2004 | I4: Índice 1997 | K4: Índice 1997 | L4: Argentina | O4: 2004=1 | P4: 1997=100 | Q4: sin imp | R4: con imp | T4: 2012=100
A5: Promedio 1959-1972 | N5: =AVERAGE(N30:N43) -> 2.6316429e-11 | O5: =AVERAGE(O30:O43) -> 2.080443e-12 | P5: =AVERAGE(P30:P43) -> 66.332426 | Q5: =AVERAGE(Q30:Q43) -> 67.349656 | R5: =AVERAGE(R30:R43) -> 63.658031 | S5: =AVERAGE(S30:S43) -> 0.23247143 | T5: =AVERAGE(T30:T43) -> 41.703571 | V5: =AVERAGE(V30:V43) -> 2.3738204e-11 | W5: =AVERAGE(W30:W43) -> 0.91630821 | Z5: =AVERAGE(Z30:Z43) -> 2.3738204e-11 | AA5: =AVERAGE(AA30:AA43) -> 0.91630821 | AD5: =AVERAGE(AD30:AD43) -> 2.3738204e-11 | AE5: =AVERAGE(AE30:AE43) -> 0.91630821 | AH5: =AVERAGE(AH30:AH43) -> 2.4285678e-11 | AI5: =AVERAGE(AI30:AI43) -> 0.91249691
A7: =A8-1 -> 1936 | C7: 2.94e-13 | E7: 0.223 | F7: 0.186 | G7: 38390 | H7: =G7 -> 38390 | I7: =H7/H$68*100 -> 13.43852 | J7: 5194000 | K7: =J7/J$68*100 -> 41.62748 | L7: =I7/K7*100 -> 32.282811 | N7: 3.01e-13 | O7: 1.1740506e-14 | P7: =L7 -> 32.282811 | Q7: =Q8*P7/P8 -> 32.777879 | R7: =R8*P7/P8 -> 30.98123 | S7: 0.09619 | T7: =T8*'Largo Plazo'!O7/'Largo Plazo'!O8 -> 19.973403 | V7: =N$5*((O7/O$5)/(S7/S$5))*((T7/T$5)/(P7/P$5)) -> 3.5320835e-13 | W7: =V7/N7 -> 1.1734497 | X7: =W7/W$5 -> 1.2806277 | Y7: =N7*X7 -> 3.8546893e-13 | Z7: =N$5*((O7/O$5)/(S7/S$5))*((T7/T$5)/(Q7/Q$5)) -> 3.5320835e-13 | AA7: =Z7/N7 -> 1.1734497 | AB7: =AA7/AA$5 -> 1.2806277 | AC7: =N7*AB7 -> 3.8546893e-13 | AD7: =N$5*((O7/O$5)/(S7/S$5))*((T7/T$5)/(R7/R$5)) -> 3.5320835e-13 | AE7: =AD7/N7 -> 1.1734497 | AF7: =AE7/AE$5 -> 1.2806277 | AG7: =N7*AF7 -> 3.8546893e-13 | AH7: =N$5*((O7/O$5)/(S7/S$5)) -> 3.5891996e-13 | AI7: =AH7/N7 -> 1.1924251 | AJ7: =AI7/AI$5 -> 1.3067717 | AK7: =N7*AJ7 -> 3.9333827e-13 | AM7: =Y7/C7-1 -> 0.31111881 | AN7: =AC7/C7-1 -> 0.31111881 | AO7: =AG7/C7-1 -> 0.31111881
A8: =A9-1 -> 1937 | C8: 2.87e-13 | E8: 0.225 | F8: 0.185 | G8: 41172 | H8: =G8 -> 41172 | I8: =H8/H$68*100 -> 14.412367 | J8: 5449000 | K8: =J8/J$68*100 -> 43.671185 | L8: =I8/K8*100 -> 33.002005 | N8: 3.03e-13 | O8: 1.2050633e-14 | P8: =L8 -> 33.002005 | Q8: =Q9*P8/P9 -> 33.508103 | R8: =R9*P8/P9 -> 31.671428 | S8: 0.09965 | T8: =T9*'Largo Plazo'!O8/'Largo Plazo'!O9 -> 19.866019 | V8: =N$5*((O8/O$5)/(S8/S$5))*((T8/T$5)/(P8/P$5)) -> 3.4048376e-13 | W8: =V8/N8 -> 1.1237088 | X8: =W8/W$5 -> 1.2263437 | Y8: =N8*X8 -> 3.7158213e-13 | Z8: =N$5*((O8/O$5)/(S8/S$5))*((T8/T$5)/(Q8/Q$5)) -> 3.4048376e-13 | AA8: =Z8/N8 -> 1.1237088 | AB8: =AA8/AA$5 -> 1.2263437 | AC8: =N8*AB8 -> 3.7158213e-13 | AD8: =N$5*((O8/O$5)/(S8/S$5))*((T8/T$5)/(R8/R$5)) -> 3.4048376e-13 | AE8: =AD8/N8 -> 1.1237088 | AF8: =AE8/AE$5 -> 1.2263437 | AG8: =N8*AF8 -> 3.7158213e-13 | AH8: =N$5*((O8/O$5)/(S8/S$5)) -> 3.5560942e-13 | AI8: =AH8/N8 -> 1.1736285 | AJ8: =AI8/AI$5 -> 1.2861725 | AK8: =N8*AJ8 -> 3.8971027e-13 | AM8: =Y8/C8-1 -> 0.29471127 | AN8: =AC8/C8-1 -> 0.29471127 | AO8: =AG8/C8-1 -> 0.29471127
A9: =A10-1 -> 1938 | C9: 2.64e-13 | E9: 0.224 | F9: 0.167 | G9: 41299 | H9: =G9 -> 41299 | I9: =H9/H$68*100 -> 14.456824 | J9: 5424000 | K9: =J9/J$68*100 -> 43.470822 | L9: =I9/K9*100 -> 33.256384 | N9: 3.07e-13 | O9: 1.1968354e-14 | P9: =L9 -> 33.256384 | Q9: =Q10*P9/P10 -> 33.766382 | R9: =R10*P9/P10 -> 31.915551 | S9: 0.09758 | T9: =T10*'Largo Plazo'!O9/'Largo Plazo'!O10 -> 17.933109 | V9: =N$5*((O9/O$5)/(S9/S$5))*((T9/T$5)/(P9/P$5)) -> 3.0934815e-13 | W9: =V9/N9 -> 1.0076487 | X9: =W9/W$5 -> 1.0996831 | Y9: =N9*X9 -> 3.3760272e-13 | Z9: =N$5*((O9/O$5)/(S9/S$5))*((T9/T$5)/(Q9/Q$5)) -> 3.0934815e-13 | AA9: =Z9/N9 -> 1.0076487 | AB9: =AA9/AA$5 -> 1.0996831 | AC9: =N9*AB9 -> 3.3760272e-13 | AD9: =N$5*((O9/O$5)/(S9/S$5))*((T9/T$5)/(R9/R$5)) -> 3.0934815e-13 | AE9: =AD9/N9 -> 1.0076487 | AF9: =AE9/AE$5 -> 1.0996831 | AG9: =N9*AF9 -> 3.3760272e-13 | AH9: =N$5*((O9/O$5)/(S9/S$5)) -> 3.6067358e-13 | AI9: =AH9/N9 -> 1.1748325 | AJ9: =AI9/AI$5 -> 1.287492 | AK9: =N9*AJ9 -> 3.9526006e-13 | AM9: =Y9/C9-1 -> 0.2787982 | AN9: =AC9/C9-1 -> 0.2787982 | AO9: =AG9/C9-1 -> 0.2787982
A10: =A11-1 -> 1939 | C10: 2.9e-13 | E10: 0.226 | F10: 0.179 | G10: 42879 | H10: =G10 -> 42879 | I10: =H10/H$68*100 -> 15.009907 | J10: 5640000 | K10: =J10/J$68*100 -> 45.201961 | L10: =I10/K10*100 -> 33.206318 | N10: 3.27e-13 | O10: 1.2158228e-14 | P10: =L10 -> 33.206318 | Q10: =Q11*P10/P11 -> 33.715548 | R10: =R11*P10/P11 -> 31.867503 | S10: 0.09619 | T10: =T11*'Largo Plazo'!O10/'Largo Plazo'!O11 -> 19.221716 | V10: =N$5*((O10/O$5)/(S10/S$5))*((T10/T$5)/(P10/P$5)) -> 3.4221979e-13 | W10: =V10/N10 -> 1.0465437 | X10: =W10/W$5 -> 1.1421306 | Y10: =N10*X10 -> 3.7347672e-13 | Z10: =N$5*((O10/O$5)/(S10/S$5))*((T10/T$5)/(Q10/Q$5)) -> 3.4221979e-13 | AA10: =Z10/N10 -> 1.0465437 | AB10: =AA10/AA$5 -> 1.1421306 | AC10: =N10*AB10 -> 3.7347672e-13 | AD10: =N$5*((O10/O$5)/(S10/S$5))*((T10/T$5)/(R10/R$5)) -> 3.4221979e-13 | AE10: =AD10/N10 -> 1.0465437 | AF10: =AE10/AE$5 -> 1.1421306 | AG10: =N10*AF10 -> 3.7347672e-13 | AH10: =N$5*((O10/O$5)/(S10/S$5)) -> 3.7169016e-13 | AI10: =AH10/N10 -> 1.1366671 | AJ10: =AI10/AI$5 -> 1.2456668 | AK10: =N10*AJ10 -> 4.0733305e-13 | AM10: =Y10/C10-1 -> 0.28785077 | AN10: =AC10/C10-1 -> 0.28785077 | AO10: =AG10/C10-1 -> 0.28785077
A11: =A12-1 -> 1940 | C11: 3.33e-13 | E11: 0.22 | F11: 0.197 | G11: 43575 | H11: =G11 -> 43575 | I11: =H11/H$68*100 -> 15.253543 | J11: 5635000 | K11: =J11/J$68*100 -> 45.161888 | L11: =I11/K11*100 -> 33.775256 | N11: 3.36e-13 | O11: 1.243038e-14 | P11: =L11 -> 33.775256 | Q11: =Q12*P11/P12 -> 34.293211 | R11: =R12*P11/P12 -> 32.413503 | S11: 0.09689 | T11: =T12*'Largo Plazo'!O11/'Largo Plazo'!O12 -> 21.154626 | V11: =N$5*((O11/O$5)/(S11/S$5))*((T11/T$5)/(P11/P$5)) -> 3.7584214e-13 | W11: =V11/N11 -> 1.1185778 | X11: =W11/W$5 -> 1.220744 | Y11: =N11*X11 -> 4.1017e-13 | Z11: =N$5*((O11/O$5)/(S11/S$5))*((T11/T$5)/(Q11/Q$5)) -> 3.7584214e-13 | AA11: =Z11/N11 -> 1.1185778 | AB11: =AA11/AA$5 -> 1.220744 | AC11: =N11*AB11 -> 4.1017e-13 | AD11: =N$5*((O11/O$5)/(S11/S$5))*((T11/T$5)/(R11/R$5)) -> 3.7584214e-13 | AE11: =AD11/N11 -> 1.1185778 | AF11: =AE11/AE$5 -> 1.220744 | AG11: =N11*AF11 -> 4.1017e-13 | AH11: =N$5*((O11/O$5)/(S11/S$5)) -> 3.7726468e-13 | AI11: =AH11/N11 -> 1.1228115 | AJ11: =AI11/AI$5 -> 1.2304826 | AK11: =N11*AJ11 -> 4.1344214e-13 | AM11: =Y11/C11-1 -> 0.23174173 | AN11: =AC11/C11-1 -> 0.23174173 | AO11: =AG11/C11-1 -> 0.23174173
A12: =A13-1 -> 1941 | C12: 3.58e-13 | E12: 0.206 | F12: 0.204 | G12: 45852 | H12: =G12 -> 45852 | I12: =H12/H$68*100 -> 16.050613 | J12: 5783000 | K12: =J12/J$68*100 -> 46.348039 | L12: =I12/K12*100 -> 34.63062 | N12: 3.36e-13 | O12: 1.2759494e-14 | P12: =L12 -> 34.63062 | Q12: =Q13*P12/P13 -> 35.161692 | R12: =R13*P12/P13 -> 33.23438 | S12: 0.1017 | T12: =T13*'Largo Plazo'!O12/'Largo Plazo'!O13 -> 21.906313 | V12: =N$5*((O12/O$5)/(S12/S$5))*((T12/T$5)/(P12/P$5)) -> 3.7120588e-13 | W12: =V12/N12 -> 1.1047794 | X12: =W12/W$5 -> 1.2056854 | Y12: =N12*X12 -> 4.0511028e-13 | Z12: =N$5*((O12/O$5)/(S12/S$5))*((T12/T$5)/(Q12/Q$5)) -> 3.7120588e-13 | AA12: =Z12/N12 -> 1.1047794 | AB12: =AA12/AA$5 -> 1.2056854 | AC12: =N12*AB12 -> 4.0511028e-13 | AD12: =N$5*((O12/O$5)/(S12/S$5))*((T12/T$5)/(R12/R$5)) -> 3.7120588e-13 | AE12: =AD12/N12 -> 1.1047794 | AF12: =AE12/AE$5 -> 1.2056854 | AG12: =N12*AF12 -> 4.0511028e-13 | AH12: =N$5*((O12/O$5)/(S12/S$5)) -> 3.6893783e-13 | AI12: =AH12/N12 -> 1.0980293 | AJ12: =AI12/AI$5 -> 1.2033238 | AK12: =N12*AJ12 -> 4.043168e-13 | AM12: =Y12/C12-1 -> 0.13159296 | AN12: =AC12/C12-1 -> 0.13159296 | AO12: =AG12/C12-1 -> 0.13159296
A13: =A14-1 -> 1942 | C13: 3.56e-13 | E13: 0.196 | F13: 0.202 | G13: 46358 | H13: =G13 -> 46358 | I13: =H13/H$68*100 -> 16.22774 | J13: 5654000 | K13: =J13/J$68*100 -> 45.314164 | L13: =I13/K13*100 -> 35.811628 | N13: 3.36e-13 | O13: 1.3487342e-14 | P13: =L13 -> 35.811628 | Q13: =Q14*P13/P14 -> 36.360811 | R13: =R14*P13/P14 -> 34.367772 | S13: 0.1128 | T13: =T14*'Largo Plazo'!O13/'Largo Plazo'!O14 -> 21.691545 | V13: =N$5*((O13/O$5)/(S13/S$5))*((T13/T$5)/(P13/P$5)) -> 3.3874822e-13 | W13: =V13/N13 -> 1.0081792 | X13: =W13/W$5 -> 1.1002621 | Y13: =N13*X13 -> 3.6968808e-13 | Z13: =N$5*((O13/O$5)/(S13/S$5))*((T13/T$5)/(Q13/Q$5)) -> 3.3874822e-13 | AA13: =Z13/N13 -> 1.0081792 | AB13: =AA13/AA$5 -> 1.1002621 | AC13: =N13*AB13 -> 3.6968808e-13 | AD13: =N$5*((O13/O$5)/(S13/S$5))*((T13/T$5)/(R13/R$5)) -> 3.3874822e-13 | AE13: =AD13/N13 -> 1.0081792 | AF13: =AE13/AE$5 -> 1.1002621 | AG13: =N13*AF13 -> 3.6968808e-13 | AH13: =N$5*((O13/O$5)/(S13/S$5)) -> 3.5160737e-13 | AI13: =AH13/N13 -> 1.0464505 | AJ13: =AI13/AI$5 -> 1.1467989 | AK13: =N13*AJ13 -> 3.8532445e-13 | AM13: =Y13/C13-1 -> 0.038449655 | AN13: =AC13/C13-1 -> 0.038449655 | AO13: =AG13/C13-1 -> 0.038449655
A14: =A15-1 -> 1943 | C14: 3.9e-13 | E14: 0.182 | F14: 0.215 | G14: 46042 | H14: =G14 -> 46042 | I14: =H14/H$68*100 -> 16.117123 | J14: 5362000 | K14: =J14/J$68*100 -> 42.973921 | L14: =I14/K14*100 -> 37.504428 | N14: 3.36e-13 | O14: 1.3632911e-14 | P14: =L14 -> 37.504428 | Q14: =Q15*P14/P15 -> 38.079571 | R14: =R15*P14/P15 -> 35.992322 | S14: 0.1197 | T14: =T15*'Largo Plazo'!O14/'Largo Plazo'!O15 -> 23.087536 | V14: =N$5*((O14/O$5)/(S14/S$5))*((T14/T$5)/(P14/P$5)) -> 3.2793127e-13 | W14: =V14/N14 -> 0.97598592 | X14: =W14/W$5 -> 1.0651284 | Y14: =N14*X14 -> 3.5788315e-13 | Z14: =N$5*((O14/O$5)/(S14/S$5))*((T14/T$5)/(Q14/Q$5)) -> 3.2793127e-13 | AA14: =Z14/N14 -> 0.97598592 | AB14: =AA14/AA$5 -> 1.0651284 | AC14: =N14*AB14 -> 3.5788315e-13 | AD14: =N$5*((O14/O$5)/(S14/S$5))*((T14/T$5)/(R14/R$5)) -> 3.2793127e-13 | AE14: =AD14/N14 -> 0.97598592 | AF14: =AE14/AE$5 -> 1.0651284 | AG14: =N14*AF14 -> 3.5788315e-13 | AH14: =N$5*((O14/O$5)/(S14/S$5)) -> 3.3491544e-13 | AI14: =AH14/N14 -> 0.99677214 | AJ14: =AI14/AI$5 -> 1.0923567 | AK14: =N14*AJ14 -> 3.6703186e-13 | AM14: =Y14/C14-1 -> -0.082350901 | AN14: =AC14/C14-1 -> -0.082350901 | AO14: =AG14/C14-1 -> -0.082350901
A15: =A16-1 -> 1944 | C15: 4.1e-13 | E15: 0.188 | F15: 0.239 | G15: 51228 | H15: =G15 -> 51228 | I15: =H15/H$68*100 -> 17.932496 | J15: 5857000 | K15: =J15/J$68*100 -> 46.941114 | L15: =I15/K15*100 -> 38.20211 | N15: 3.36e-13 | O15: 1.3594937e-14 | P15: =L15 -> 38.20211 | Q15: =Q16*P15/P16 -> 38.787953 | R15: =R16*P15/P16 -> 36.661875 | S15: 0.1218 | T15: =T16*'Largo Plazo'!O15/'Largo Plazo'!O16 -> 25.664749 | V15: =N$5*((O15/O$5)/(S15/S$5))*((T15/T$5)/(P15/P$5)) -> 3.5072999e-13 | W15: =V15/N15 -> 1.0438393 | X15: =W15/W$5 -> 1.1391792 | Y15: =N15*X15 -> 3.8276421e-13 | Z15: =N$5*((O15/O$5)/(S15/S$5))*((T15/T$5)/(Q15/Q$5)) -> 3.5072999e-13 | AA15: =Z15/N15 -> 1.0438393 | AB15: =AA15/AA$5 -> 1.1391792 | AC15: =N15*AB15 -> 3.8276421e-13 | AD15: =N$5*((O15/O$5)/(S15/S$5))*((T15/T$5)/(R15/R$5)) -> 3.5072999e-13 | AE15: =AD15/N15 -> 1.0438393 | AF15: =AE15/AE$5 -> 1.1391792 | AG15: =N15*AF15 -> 3.8276421e-13 | AH15: =N$5*((O15/O$5)/(S15/S$5)) -> 3.2822421e-13 | AI15: =AH15/N15 -> 0.97685776 | AJ15: =AI15/AI$5 -> 1.0705327 | AK15: =N15*AJ15 -> 3.5969898e-13 | AM15: =Y15/C15-1 -> -0.066428751 | AN15: =AC15/C15-1 -> -0.066428751 | AO15: =AG15/C15-1 -> -0.066428751
